Workbook

Sheet Raw_Shipments
A1: ShipmentID | B1: OrderID | C1: SupplierID | D1: ShipDate | E1: PromisedDate | F1: ActualDeliveryDate | G1: Carrier | H1: QtyShipped | I1: Quantity_ordered | J1: On_Time | K1: In_Full | L1: OTIF | M1: OTIF_Flag(1/0)
A2: SHP-00001 | B2: ORD-00001 | C2: SUP-02 | D2: 45659 | E2: 45668 | F2: 45666 | G2: DHL | H2: 11 | I2: =IFERROR(INDEX(Raw_Orders!H2:H2430,MATCH(B2,Raw_Orders!A2:A2430,0)),0) -> 11 | J2: =IF(E2>=F2,"Yes","No") -> Yes | K2: =IF(H2>=I2,"Yes","N0") -> Yes | L2: =IF(AND(J2="Yes",K2="Yes"),"Yes","No") -> Yes | M2: =IF(L2="Yes",1,0) -> 1
A3: SHP-00002 | B3: ORD-00002 | C3: SUP-08 | D3: 45658 | E3: 45666 | F3: 45675 | G3: FedEx | H3: 6 | I3: =IFERROR(INDEX(Raw_Orders!H3:H2431,MATCH(B3,Raw_Orders!A3:A2431,0)),0) -> 9 | J3: =IF(E3>=F3,"Yes","No") -> No | K3: =IF(H3>=I3,"Yes","N0") -> N0 | L3: =IF(AND(J3="Yes",K3="Yes"),"Yes","No") -> No | M3: =IF(L3="Yes",1,0) -> 0
A4: SHP-00003 | B4: ORD-00003 | C4: SUP-08 | D4: 45658 | E4: 45662 | F4: 45673 | G4: Ekart | H4: 19 | I4: =IFERROR(INDEX(Raw_Orders!H4:H2432,MATCH(B4,Raw_Orders!A4:A2432,0)),0) -> 19 | J4: =IF(E4>=F4,"Yes","No") -> No | K4: =IF(H4>=I4,"Yes","N0") -> Yes | L4: =IF(AND(J4="Yes",K4="Yes"),"Yes","No") -> No | M4: =IF(L4="Yes",1,0) -> 0
A5: SHP-00004 | B5: ORD-00004 | C5: SUP-04 | D5: 45660 | E5: 45664 | F5: 45670 | G5: BlueDart | H5: 33 | I5: =IFERROR(INDEX(Raw_Orders!H5:H2433,MATCH(B5,Raw_Orders!A5:A2433,0)),0) -> 33 | J5: =IF(E5>=F5,"Yes","No") -> No | K5: =IF(H5>=I5,"Yes","N0") -> Yes | L5: =IF(AND(J5="Yes",K5="Yes"),"Yes","No") -> No | M5: =IF(L5="Yes",1,0) -> 0
A6: SHP-00005 | B6: ORD-00005 | C6: SUP-04 | D6: 45658 | E6: 45668 | F6: 45664 | G6: BlueDart | H6: 52 | I6: =IFERROR(INDEX(Raw_Orders!H6:H2434,MATCH(B6,Raw_Orders!A6:A2434,0)),0) -> 59 | J6: =IF(E6>=F6,"Yes","No") -> Yes | K6: =IF(H6>=I6,"Yes","N0") -> N0 | L6: =IF(AND(J6="Yes",K6="Yes"),"Yes","No") -> No | M6: =IF(L6="Yes",1,0) -> 0
A7: SHP-00006 | B7: ORD-00006 | C7: SUP-05 | D7: 45658 | E7: 45662 | F7: 45673 | G7: DHL | H7: 41 | I7: =IFERROR(INDEX(Raw_Orders!H7:H2435,MATCH(B7,Raw_Orders!A7:A2435,0)),0) -> 41 | J7: =IF(E7>=F7,"Yes","No") -> No | K7: =IF(H7>=I7,"Yes","N0") -> Yes | L7: =IF(AND(J7="Yes",K7="Yes"),"Yes","No") -> No | M7: =IF(L7="Yes",1,0) -> 0
A8: SHP-00007 | B8: ORD-00007 | C8: SUP-05 | D8: 45659 | E8: 45661 | F8: 45672 | G8: Ekart | H8: 2 | I8: =IFERROR(INDEX(Raw_Orders!H8:H2436,MATCH(B8,Raw_Orders!A8:A2436,0)),0) -> 2 | J8: =IF(E8>=F8,"Yes","No") -> No | K8: =IF(H8>=I8,"Yes","N0") -> Yes | L8: =IF(AND(J8="Yes",K8="Yes"),"Yes","No") -> No | M8: =IF(L8="Yes",1,0) -> 0
A9: SHP-00008 | B9: ORD-00008 | C9: SUP-05 | D9: 45659 | E9: 45666 | F9: 45672 | G9: DHL | H9: 4 | I9: =IFERROR(INDEX(Raw_Orders!H9:H2437,MATCH(B9,Raw_Orders!A9:A2437,0)),0) -> 12 | J9: =IF(E9>=F9,"Yes","No") -> No | K9: =IF(H9>=I9,"Yes","N0") -> N0 | L9: =IF(AND(J9="Yes",K9="Yes"),"Yes","No") -> No | M9: =IF(L9="Yes",1,0) -> 0
A10: SHP-00009 | B10: ORD-00009 | C10: SUP-06 | D10: 45660 | E10: 45664 | F10: 45668 | G10: BlueDart | H10: 27 | I10: =IFERROR(INDEX(Raw_Orders!H10:H2438,MATCH(B10,Raw_Orders!A10:A2438,0)),0) -> 27 | J10: =IF(E10>=F10,"Yes","No") -> No | K10: =IF(H10>=I10,"Yes","N0") -> Yes | L10: =IF(AND(J10="Yes",K10="Yes"),"Yes","No") -> No | M10: =IF(L10="Yes",1,0) -> 0
A11: SHP-00010 | B11: ORD-00010 | C11: SUP-01 | D11: 45660 | E11: 45663 | F11: 45673 | G11: Ekart | H11: 16 | I11: =IFERROR(INDEX(Raw_Orders!H11:H2439,MATCH(B11,Raw_Orders!A11:A2439,0)),0) -> 16 | J11: =IF(E11>=F11,"Yes","No") -> No | K11: =IF(H11>=I11,"Yes","N0") -> Yes | L11: =IF(AND(J11="Yes",K11="Yes"),"Yes","No") -> No | M11: =IF(L11="Yes",1,0) -> 0
A12: SHP-00011 | B12: ORD-00011 | C12: SUP-06 | D12: 45659 | E12: 45663 | F12: 45670 | G12: Delhivery | H12: 59 | I12: =IFERROR(INDEX(Raw_Orders!H12:H2440,MATCH(B12,Raw_Orders!A12:A2440,0)),0) -> 59 | J12: =IF(E12>=F12,"Yes","No") -> No | K12: =IF(H12>=I12,"Yes","N0") -> Yes | L12: =IF(AND(J12="Yes",K12="Yes"),"Yes","No") -> No | M12: =IF(L12="Yes",1,0) -> 0
A13: SHP-00012 | B13: ORD-00012 | C13: SUP-02 | D13: 45659 | E13: 45669 | F13: 45666 | G13: BlueDart | H13: 14 | I13: =IFERROR(INDEX(Raw_Orders!H13:H2441,MATCH(B13,Raw_Orders!A13:A2441,0)),0) -> 14 | J13: =IF(E13>=F13,"Yes","No") -> Yes | K13: =IF(H13>=I13,"Yes","N0") -> Yes | L13: =IF(AND(J13="Yes",K13="Yes"),"Yes","No") -> Yes | M13: =IF(L13="Yes",1,0) -> 1
... A2430: SHP-02429 | B2430: ORD-02429 | C2430: SUP-05 | D2430: 46023 | E2430: 46027 | F2430: 46037 | G2430: Ekart | H2430: 10 | I2430: =IFERROR(INDEX(Raw_Orders!H2430:H4858,MATCH(B2430,Raw_Orders!A2430:A4858,0)),0) -> 10 | J2430: =IF(E2430>=F2430,"Yes","No") -> No | K2430: =IF(H2430>=I2430,"Yes","N0") -> Yes | L2430: =IF(AND(J2430="Yes",K2430="Yes"),"Yes","No") -> No | M2430: =IF(L2430="Yes",1,0) -> 0

Sheet Raw_Orders
A1: OrderID | B1: OrderDate | C1: CustomerID | D1: Region | E1: SKU | F1: ProductName | G1: Category | H1: Qty_Ordered | I1: Unit_Price | J1: Promised_Date | K1: Order_Value | L1: Delivery_status
A2: ORD-00001 | B2: 45658 | C2: CUST-115 | D2: South | E2: SKU-006 | F2: Running Shoes | G2: Apparel | H2: 11 | I2: 183.06 | J2: 45668 | K2: =I2*H2 -> 2013.66 | L2: =INDEX(Raw_Shipments!L2:L2430,MATCH(A2,Raw_Shipments!B2:B2430)) -> Yes
A3: ORD-00002 | B3: 45658 | C3: CUST-102 | D3: South | E3: SKU-007 | F3: Non-stick Pan | G3: Home & Kitchen | H3: 9 | I3: 2108.56 | J3: 45666 | K3: =I3*H3 -> 18977.04 | L3: =INDEX(Raw_Shipments!L3:L2431,MATCH(A3,Raw_Shipments!B3:B2431)) -> No
A4: ORD-00003 | B4: 45658 | C4: CUST-104 | D4: East | E4: SKU-009 | F4: LED Lamp | G4: Home & Kitchen | H4: 19 | I4: 1646.8 | J4: 45662 | K4: =I4*H4 -> 31289.2 | L4: =INDEX(Raw_Shipments!L4:L2432,MATCH(A4,Raw_Shipments!B4:B2432)) -> No
A5: ORD-00004 | B5: 45658 | C5: CUST-135 | D5: West | E5: SKU-010 | F5: Basmati Rice 5kg | G5: Groceries | H5: 33 | I5: 689 | J5: 45664 | K5: =I5*H5 -> 22737 | L5: =INDEX(Raw_Shipments!L5:L2433,MATCH(A5,Raw_Shipments!B5:B2433)) -> No
A6: ORD-00005 | B6: 45658 | C6: CUST-131 | D6: West | E6: SKU-011 | F6: Cooking Oil 1L | G6: Groceries | H6: 59 | I6: 1064.79 | J6: 45668 | K6: =I6*H6 -> 62822.61 | L6: =INDEX(Raw_Shipments!L6:L2434,MATCH(A6,Raw_Shipments!B6:B2434)) -> No
A7: ORD-00006 | B7: 45658 | C7: CUST-184 | D7: West | E7: SKU-013 | F7: Yoga Mat | G7: Sports | H7: 41 | I7: 2445.11 | J7: 45662 | K7: =I7*H7 -> 100249.51 | L7: =INDEX(Raw_Shipments!L7:L2435,MATCH(A7,Raw_Shipments!B7:B2435)) -> No
A8: ORD-00007 | B8: 45658 | C8: CUST-186 | D8: North | E8: SKU-014 | F8: Cricket Bat | G8: Sports | H8: 2 | I8: 1833.14 | J8: 45661 | K8: =I8*H8 -> 3666.28 | L8: =INDEX(Raw_Shipments!L8:L2436,MATCH(A8,Raw_Shipments!B8:B2436)) -> No
A9: ORD-00008 | B9: 45658 | C9: CUST-113 | D9: South | E9: SKU-015 | F9: Football | G9: Sports | H9: 12 | I9: 1952.28 | J9: 45666 | K9: =I9*H9 -> 23427.36 | L9: =INDEX(Raw_Shipments!L9:L2437,MATCH(A9,Raw_Shipments!B9:B2437)) -> No
A10: ORD-00009 | B10: 45659 | C10: CUST-135 | D10: West | E10: SKU-001 | F10: Wireless Mouse | G10: Electronics | H10: 27 | I10: 2055.9 | J10: 45664 | K10: =I10*H10 -> 55509.3 | L10: =INDEX(Raw_Shipments!L10:L2438,MATCH(A10,Raw_Shipments!B10:B2438)) -> No
A11: ORD-00010 | B11: 45659 | C11: CUST-156 | D11: North | E11: SKU-002 | F11: Bluetooth Speaker | G11: Electronics | H11: 16 | I11: 1695.1 | J11: 45663 | K11: =I11*H11 -> 27121.6 | L11: =INDEX(Raw_Shipments!L11:L2439,MATCH(A11,Raw_Shipments!B11:B2439)) -> No
A12: ORD-00011 | B12: 45659 | C12: CUST-196 | D12: South | E12: SKU-003 | F12: USB-C Charger | G12: Electronics | H12: 59 | I12: 2555.22 | J12: 45663 | K12: =I12*H12 -> 150757.98 | L12: =INDEX(Raw_Shipments!L12:L2440,MATCH(A12,Raw_Shipments!B12:B2440)) -> No
A13: ORD-00012 | B13: 45659 | C13: CUST-161 | D13: South | E13: SKU-004 | F13: Cotton T-Shirt | G13: Apparel | H13: 14 | I13: 850.8 | J13: 45669 | K13: =I13*H13 -> 11911.2 | L13: =INDEX(Raw_Shipments!L13:L2441,MATCH(A13,Raw_Shipments!B13:B2441)) -> Yes
... A2430: ORD-02429 | B2430: 46022 | C2430: CUST-104 | D2430: North | E2430: SKU-014 | F2430: Cricket Bat | G2430: Sports | H2430: 10 | I2430: 1833.14 | J2430: 46027 | K2430: =I2430*H2430 -> 18331.4 | L2430: =INDEX(Raw_Shipments!L2430:L4858,MATCH(A2430,Raw_Shipments!B2430:B4858)) -> No

Sheet Raw_Inventory
A1: SKU | B1: ProductName | C1: Category | D1: Warehouse | E1: UnitCost | F1: UnitPrice | G1: StockOnHand | H1: LeadTimeDays | I1: OrderingCost | J1: HoldingCostPct | K1: Annual _Demand | L1: Average_Daily _Demand
A2: SKU-001 | B2: Wireless Mouse | C2: Electronics | D2: WH-Delhi | E2: 1283.44 | F2: 2055.9 | G2: 467 | H2: 7 | I2: 658 | J2: 0.19 | K2: =SUMIF(Raw_Orders!$E$2:$E$2430,A2,Raw_Orders!$H$2:$H$2430) -> 5490 | L2: =K2/365 -> 15.041096
A3: SKU-002 | B3: Bluetooth Speaker | C3: Electronics | D3: WH-Delhi | E3: 972.67 | F3: 1695.1 | G3: 126 | H3: 13 | I3: 1823 | J3: 0.27 | K3: =SUMIF(Raw_Orders!$E$2:$E$2430,A3,Raw_Orders!$H$2:$H$2430) -> 3052 | L3: =K3/365 -> 8.3616438
A4: SKU-003 | B4: USB-C Charger | C4: Electronics | D4: WH-Chennai | E4: 1479.01 | F4: 2555.22 | G4: 544 | H4: 7 | I4: 1771 | J4: 0.2 | K4: =SUMIF(Raw_Orders!$E$2:$E$2430,A4,Raw_Orders!$H$2:$H$2430) -> 6135 | L4: =K4/365 -> 16.808219
A5: SKU-004 | B5: Cotton T-Shirt | C5: Apparel | D5: WH-Mumbai | E5: 605.66 | F5: 850.8 | G5: 626 | H5: 5 | I5: 1958 | J5: 0.17 | K5: =SUMIF(Raw_Orders!$E$2:$E$2430,A5,Raw_Orders!$H$2:$H$2430) -> 2195 | L5: =K5/365 -> 6.0136986
A6: SKU-005 | B6: Denim Jacket | C6: Apparel | D6: WH-Chennai | E6: 618.83 | F6: 1110.65 | G6: 866 | H6: 5 | I6: 2052 | J6: 0.18 | K6: =SUMIF(Raw_Orders!$E$2:$E$2430,A6,Raw_Orders!$H$2:$H$2430) -> 4713 | L6: =K6/365 -> 12.912329
A7: SKU-006 | B7: Running Shoes | C7: Apparel | D7: WH-Chennai | E7: 125.58 | F7: 183.06 | G7: 297 | H7: 5 | I7: 1811 | J7: 0.21 | K7: =SUMIF(Raw_Orders!$E$2:$E$2430,A7,Raw_Orders!$H$2:$H$2430) -> 2298 | L7: =K7/365 -> 6.2958904
A8: SKU-007 | B8: Non-stick Pan | C8: Home & Kitchen | D8: WH-Chennai | E8: 1378.66 | F8: 2108.56 | G8: 844 | H8: 4 | I8: 1669 | J8: 0.28 | K8: =SUMIF(Raw_Orders!$E$2:$E$2430,A8,Raw_Orders!$H$2:$H$2430) -> 2349 | L8: =K8/365 -> 6.4356164
A9: SKU-008 | B9: Air Fryer | C9: Home & Kitchen | D9: WH-Delhi | E9: 647.15 | F9: 912.26 | G9: 853 | H9: 15 | I9: 594 | J9: 0.17 | K9: =SUMIF(Raw_Orders!$E$2:$E$2430,A9,Raw_Orders!$H$2:$H$2430) -> 7188 | L9: =K9/365 -> 19.693151
A10: SKU-009 | B10: LED Lamp | C10: Home & Kitchen | D10: WH-Kolkata | E10: 970.97 | F10: 1646.8 | G10: 470 | H10: 4 | I10: 1692 | J10: 0.22 | K10: =SUMIF(Raw_Orders!$E$2:$E$2430,A10,Raw_Orders!$H$2:$H$2430) -> 3312 | L10: =K10/365 -> 9.0739726
A11: SKU-010 | B11: Basmati Rice 5kg | C11: Groceries | D11: WH-Chennai | E11: 437.01 | F11: 689 | G11: 867 | H11: 6 | I11: 1782 | J11: 0.17 | K11: =SUMIF(Raw_Orders!$E$2:$E$2430,A11,Raw_Orders!$H$2:$H$2430) -> 6537 | L11: =K11/365 -> 17.909589
A12: SKU-011 | B12: Cooking Oil 1L | C12: Groceries | D12: WH-Mumbai | E12: 697.37 | F12: 1064.79 | G12: 599 | H12: 6 | I12: 2325 | J12: 0.28 | K12: =SUMIF(Raw_Orders!$E$2:$E$2430,A12,Raw_Orders!$H$2:$H$2430) -> 7087 | L12: =K12/365 -> 19.416438
A13: SKU-012 | B13: Green Tea Pack | C13: Groceries | D13: WH-Chennai | E13: 503.79 | F13: 815.88 | G13: 860 | H13: 6 | I13: 823 | J13: 0.29 | K13: =SUMIF(Raw_Orders!$E$2:$E$2430,A13,Raw_Orders!$H$2:$H$2430) -> 4365 | L13: =K13/365 -> 11.958904
... A16: SKU-015 | B16: Football | C16: Sports | D16: WH-Mumbai | E16: 1160.06 | F16: 1952.28 | G16: 351 | H16: 13 | I16: 1555 | J16: 0.24 | K16: =SUMIF(Raw_Orders!$E$2:$E$2430,A16,Raw_Orders!$H$2:$H$2430) -> 1459 | L16: =K16/365 -> 3.9972603

Sheet Raw_Suppliers
A1: SupplierID | B1: SupplierName | C1: Category | D1: Country | E1: AvgLeadTimeDays | F1: OTIF_Target | G1: QualityRating | H1: CostIndex | I1: Actual_OTIF%
A2: SUP-01 | B2: Reliable Components Pvt Ltd | C2: Electronics | D2: India | E2: 13 | F2: 0.86 | G2: 4.6 | H2: 0.95 | I2: =AVERAGEIFS(Raw_Shipments!M2:M2430,Raw_Shipments!C2:C2430,A2) -> 0
A3: SUP-02 | B3: Global Textile Works | C3: Apparel | D3: Bangladesh | E3: 5 | F3: 0.94 | G3: 4.5 | H3: 1.21 | I3: =AVERAGEIFS(Raw_Shipments!M3:M2431,Raw_Shipments!C3:C2431,A3) -> 0.45882353
A4: SUP-03 | B4: HomeCraft Manufacturing | C4: Home & Kitchen | D4: India | E4: 4 | F4: 0.92 | G4: 3.5 | H4: 0.89 | I4: =AVERAGEIFS(Raw_Shipments!M4:M2432,Raw_Shipments!C4:C2432,A4) -> 0.54545455
A5: SUP-04 | B5: FreshSource Foods | C5: Groceries | D5: India | E5: 6 | F5: 0.91 | G5: 3.5 | H5: 0.93 | I5: =AVERAGEIFS(Raw_Shipments!M5:M2433,Raw_Shipments!C5:C2433,A5) -> 0.34631148
A6: SUP-05 | B6: ActiveGear Industries | C6: Sports | D6: Vietnam | E6: 13 | F6: 0.93 | G6: 4.1 | H6: 1.03 | I6: =AVERAGEIFS(Raw_Shipments!M6:M2434,Raw_Shipments!C6:C2434,A6) -> 0
A7: SUP-06 | B7: TechParts International | C7: Electronics | D7: China | E7: 7 | F7: 0.95 | G7: 3.5 | H7: 1.17 | I7: =AVERAGEIFS(Raw_Shipments!M7:M2435,Raw_Shipments!C7:C2435,A7) -> 0.24603175
A8: SUP-07 | B8: Prime Apparel Co | C8: Apparel | D8: India | E8: 14 | F8: 0.9 | G8: 3.9 | H8: 0.94 | I8: =AVERAGEIFS(Raw_Shipments!M8:M2436,Raw_Shipments!C8:C2436,A8) -> 0
A9: SUP-08 | B9: KitchenWorks Ltd | C9: Home & Kitchen | D9: China | E9: 15 | F9: 0.89 | G9: 3.6 | H9: 0.89 | I9: =AVERAGEIFS(Raw_Shipments!M9:M2437,Raw_Shipments!C9:C2437,A9) -> 0

Sheet KPI Dashboard 
A1: Supply Chain KPI Dashboard
A2: Every figure below is a live formula reading from the raw sheets - nothing is typed in
A4: ORDER FULFIMENT KPIs
A5: =COUNTA(Raw_Orders!A2:A2430) -> 2429 | C5: =SUM(Raw_Orders!K2:K2430) -> 88084091 | E5: =AVERAGE(Raw_Orders!K2:K2430) -> 36263.52 | G5: =COUNTIF(Raw_Shipments!J2:J2430,"Yes")/COUNTA(Raw_Shipments!J2:J2430) -> 0.23260601
A6: Total Orders | C6: Total order Value(₹) | E6: Avg Order Value(₹) | G6: On-Time%
A8: =COUNTIF(Raw_Shipments!K2:K2430,"Yes")/COUNTA(Raw_Shipments!K2:K2430) -> 0.81556196 | C8: =COUNTIF(Raw_Shipments!L2:L2430,"Yes")/COUNTA(Raw_Shipments!L2:L2430) -> 0.19555373 | E8: =COUNTIF(Raw_Shipments!M2:M2430,1)/COUNTA(Raw_Shipments!M2:M2430) -> 0.19555373 | G8: =AVERAGE(Raw_Shipments!F2:F2430-Raw_Shipments!D2:D2430) -> 13
A9: In-Full % | C9: OTIF % | E9: Perfect Order Rate | G9: Avg Fulfilment lead Time
A12: INVENTORY KPIs
A13: Metric | F13: Value
A14: Total Inventory Value | F14: =SUMPRODUCT(Raw_Inventory!E2:E16,Raw_Inventory!G2:G16) -> 7602845.2
A15: Est Annual COGS | F15: =SUMPRODUCT(Raw_Inventory!K2:K16,Raw_Inventory!E2:E16) -> 54074486
A16: Inventory Turnover | F16: =F15/F14 -> 7.1124013
A17: Days inventory Outstanding | F17: =365/F16 -> 51.318814
A19: SALES BY REAGION | F19: SALES BY CATEGORY
A20: Region | B20: Total Order Value | C20: Order count | D20: Avg Order value | F20: Category | G20: Total Order Value | H20: Order Count
A21: North | B21: =SUMIF(Raw_Orders!$D$2:$D$2430,Table5[[#This Row],[Column1]],Raw_Orders!$K$2:$K$2430) -> 20973830 | C21: =COUNTIF(Raw_Orders!$D$2:$D$2430,Table5[[#This Row],[Column1]]) -> 576 | D21: =AVERAGEIF(Raw_Orders!$D$2:$D$2430,Table5[[#This Row],[Column1]],Raw_Orders!$K$2:$K$2430) -> 36412.899 | F21: Apparel | G21: =SUMIF(Raw_Orders!$G$2:$G$2430,'KPI Dashboard '!F21,Raw_Orders!$K$2:$K$2430) -> 7522671.3 | H21: =COUNTIF(Raw_Orders!G2:G2430,'KPI Dashboard '!F21) -> 473
A22: South | B22: =SUMIF(Raw_Orders!$D$2:$D$2430,Table5[[#This Row],[Column1]],Raw_Orders!$K$2:$K$2430) -> 23181775 | C22: =COUNTIF(Raw_Orders!$D$2:$D$2430,Table5[[#This Row],[Column1]]) -> 643 | D22: =AVERAGEIF(Raw_Orders!$D$2:$D$2430,Table5[[#This Row],[Column1]],Raw_Orders!$K$2:$K$2430) -> 36052.527 | F22: Electronics | G22: =SUMIF(Raw_Orders!$G$2:$G$2430,'KPI Dashboard '!F22,Raw_Orders!$K$2:$K$2430) -> 32136611 | H22: =COUNTIF(Raw_Orders!G3:G2431,'KPI Dashboard '!F22) -> 478
A23: East | B23: =SUMIF(Raw_Orders!$D$2:$D$2430,Table5[[#This Row],[Column1]],Raw_Orders!$K$2:$K$2430) -> 20960332 | C23: =COUNTIF(Raw_Orders!$D$2:$D$2430,Table5[[#This Row],[Column1]]) -> 595 | D23: =AVERAGEIF(Raw_Orders!$D$2:$D$2430,Table5[[#This Row],[Column1]],Raw_Orders!$K$2:$K$2430) -> 35227.448 | F23: Groceries | G23: =SUMIF(Raw_Orders!$G$2:$G$2430,'KPI Dashboard '!F23,Raw_Orders!$K$2:$K$2430) -> 15611476 | H23: =COUNTIF(Raw_Orders!G4:G2432,'KPI Dashboard '!F23) -> 488
A24: West | B24: =SUMIF(Raw_Orders!$D$2:$D$2430,Table5[[#This Row],[Column1]],Raw_Orders!$K$2:$K$2430) -> 22968154 | C24: =COUNTIF(Raw_Orders!$D$2:$D$2430,Table5[[#This Row],[Column1]]) -> 615 | D24: =AVERAGEIF(Raw_Orders!$D$2:$D$2430,Table5[[#This Row],[Column1]],Raw_Orders!$K$2:$K$2430) -> 37346.592 | F24: Home & Kitchen | G24: =SUMIF(Raw_Orders!$G$2:$G$2430,'KPI Dashboard '!F24,Raw_Orders!$K$2:$K$2430) -> 16964534 | H24: =COUNTIF(Raw_Orders!G5:G2433,'KPI Dashboard '!F24) -> 487
F25: Sports | G25: =SUMIF(Raw_Orders!$G$2:$G$2430,'KPI Dashboard '!F25,Raw_Orders!$K$2:$K$2430) -> 15848799 | H25: =COUNTIF(Raw_Orders!G6:G2434,'KPI Dashboard '!F25) -> 501

Sheet ABC Analysis
A1: ABC Inventory Analysis (Pareto / 80-20 Classification)
A2: Raw Inventory is already ordered by revinue so Rack Below read straight down . Cumulative % Drice the A/B/C class
A4: Rank | B4: Product Name | C4: Annual Demand | D4: Unit Price | E4: Annual Revenue | F4: Cumulative Revenue | G4: Cumulative % | H4: ABC Class
A5: 1 | B5: =Raw_Inventory!B4 -> USB-C Charger | C5: =Raw_Inventory!K4 -> 6135 | D5: =Raw_Inventory!F4 -> 2555.22 | E5: =C5*D5 -> 15676275 | F5: =SUM($E$5:E5) -> 15676275 | G5: =F5/SUM($E$5:$E$19) -> 0.17796942 | H5: =IF(G5<=0.8,"A",IF(G5<=0.95,"B","C")) -> A
A6: 2 | B6: =Raw_Inventory!B2 -> Wireless Mouse | C6: =Raw_Inventory!K2 -> 5490 | D6: =Raw_Inventory!F2 -> 2055.9 | E6: =C6*D6 -> 11286891 | F6: =SUM($E$5:E6) -> 26963166 | G6: =F6/SUM($E$5:$E$19) -> 0.3061071 | H6: =IF(G6<=0.8,"A",IF(G6<=0.95,"B","C")) -> A
A7: 3 | B7: =Raw_Inventory!B14 -> Yoga Mat | C7: =Raw_Inventory!K14 -> 4409 | D7: =Raw_Inventory!F14 -> 2445.11 | E7: =C7*D7 -> 10780490 | F7: =SUM($E$5:E7) -> 37743656 | G7: =F7/SUM($E$5:$E$19) -> 0.42849572 | H7: =IF(G7<=0.8,"A",IF(G7<=0.95,"B","C")) -> A
A8: 4 | B8: =Raw_Inventory!B12 -> Cooking Oil 1L | C8: =Raw_Inventory!K12 -> 7087 | D8: =Raw_Inventory!F12 -> 1064.79 | E8: =C8*D8 -> 7546166.7 | F8: =SUM($E$5:E8) -> 45289822 | G8: =F8/SUM($E$5:$E$19) -> 0.51416575 | H8: =IF(G8<=0.8,"A",IF(G8<=0.95,"B","C")) -> A
A9: 5 | B9: =Raw_Inventory!B9 -> Air Fryer | C9: =Raw_Inventory!K9 -> 7188 | D9: =Raw_Inventory!F9 -> 912.26 | E9: =C9*D9 -> 6557324.9 | F9: =SUM($E$5:E9) -> 51847147 | G9: =F9/SUM($E$5:$E$19) -> 0.58860966 | H9: =IF(G9<=0.8,"A",IF(G9<=0.95,"B","C")) -> A
A10: 6 | B10: =Raw_Inventory!B10 -> LED Lamp | C10: =Raw_Inventory!K10 -> 3312 | D10: =Raw_Inventory!F10 -> 1646.8 | E10: =C10*D10 -> 5454201.6 | F10: =SUM($E$5:E10) -> 57301349 | G10: =F10/SUM($E$5:$E$19) -> 0.65053006 | H10: =IF(G10<=0.8,"A",IF(G10<=0.95,"B","C")) -> A
A11: 7 | B11: =Raw_Inventory!B6 -> Denim Jacket | C11: =Raw_Inventory!K6 -> 4713 | D11: =Raw_Inventory!F6 -> 1110.65 | E11: =C11*D11 -> 5234493.5 | F11: =SUM($E$5:E11) -> 62535842 | G11: =F11/SUM($E$5:$E$19) -> 0.70995615 | H11: =IF(G11<=0.8,"A",IF(G11<=0.95,"B","C")) -> A
A12: 8 | B12: =Raw_Inventory!B3 -> Bluetooth Speaker | C12: =Raw_Inventory!K3 -> 3052 | D12: =Raw_Inventory!F3 -> 1695.1 | E12: =C12*D12 -> 5173445.2 | F12: =SUM($E$5:E12) -> 67709288 | G12: =F12/SUM($E$5:$E$19) -> 0.76868918 | H12: =IF(G12<=0.8,"A",IF(G12<=0.95,"B","C")) -> A
A13: 9 | B13: =Raw_Inventory!B8 -> Non-stick Pan | C13: =Raw_Inventory!K8 -> 2349 | D13: =Raw_Inventory!F8 -> 2108.56 | E13: =C13*D13 -> 4953007.4 | F13: =SUM($E$5:E13) -> 72662295 | G13: =F13/SUM($E$5:$E$19) -> 0.82491962 | H13: =IF(G13<=0.8,"A",IF(G13<=0.95,"B","C")) -> B
A14: 10 | B14: =Raw_Inventory!B11 -> Basmati Rice 5kg | C14: =Raw_Inventory!K11 -> 6537 | D14: =Raw_Inventory!F11 -> 689 | E14: =C14*D14 -> 4503993 | F14: =SUM($E$5:E14) -> 77166288 | G14: =F14/SUM($E$5:$E$19) -> 0.8760525 | H14: =IF(G14<=0.8,"A",IF(G14<=0.95,"B","C")) -> B
A15: 11 | B15: =Raw_Inventory!B13 -> Green Tea Pack | C15: =Raw_Inventory!K13 -> 4365 | D15: =Raw_Inventory!F13 -> 815.88 | E15: =C15*D15 -> 3561316.2 | F15: =SUM($E$5:E15) -> 80727604 | G15: =F15/SUM($E$5:$E$19) -> 0.91648336 | H15: =IF(G15<=0.8,"A",IF(G15<=0.95,"B","C")) -> B
A16: 12 | B16: =Raw_Inventory!B16 -> Football | C16: =Raw_Inventory!K16 -> 1459 | D16: =Raw_Inventory!F16 -> 1952.28 | E16: =C16*D16 -> 2848376.5 | F16: =SUM($E$5:E16) -> 83575981 | G16: =F16/SUM($E$5:$E$19) -> 0.94882038 | H16: =IF(G16<=0.8,"A",IF(G16<=0.95,"B","C")) -> B
A17: 13 | B17: =Raw_Inventory!B15 -> Cricket Bat | C17: =Raw_Inventory!K15 -> 1211 | D17: =Raw_Inventory!F15 -> 1833.14 | E17: =C17*D17 -> 2219932.5 | F17: =SUM($E$5:E17) -> 85795913 | G17: =F17/SUM($E$5:$E$19) -> 0.9740228 | H17: =IF(G17<=0.8,"A",IF(G17<=0.95,"B","C")) -> C
A18: 14 | B18: =Raw_Inventory!B5 -> Cotton T-Shirt | C18: =Raw_Inventory!K5 -> 2195 | D18: =Raw_Inventory!F5 -> 850.8 | E18: =C18*D18 -> 1867506 | F18: =SUM($E$5:E18) -> 87663419 | G18: =F18/SUM($E$5:$E$19) -> 0.9952242 | H18: =IF(G18<=0.8,"A",IF(G18<=0.95,"B","C")) -> C
A19: 15 | B19: =Raw_Inventory!B7 -> Running Shoes | C19: =Raw_Inventory!K7 -> 2298 | D19: =Raw_Inventory!F7 -> 183.06 | E19: =C19*D19 -> 420671.88 | F19: =SUM($E$5:E19) -> 88084091 | G19: =F19/SUM($E$5:$E$19) -> 1 | H19: =IF(G19<=0.8,"A",IF(G19<=0.95,"B","C")) -> C
A21: READ: Class A = top-80% of revenue (tight control, frequent counts). Class B + next 15%. Class C = last 5% (simple, infequient review)
A23: A 3-month moving average is the simplest defensible method : it smooths random month-to-month noise while still reacting toa genuine trend. For seasonal or fast-growing demand, planners typically on to weight moving average oe exponential smoothing

Sheet Reorder EOQ Planner 
A1: Reorder Point, Safety Stock & Economic Order Quantity (EOQ) Planner
A2: Blue cell = the order deliberate business input (target service level) Demand std Dev is calculated from real monthly order history below, not assumed
A3: Target Service Level Z-score(95% = 1.65, 90% = 1.28, 99% = 2.33) | H3: 1.65
A5: SKU | B5: Product Name | C5: Average_Daily _Demand | D5: Demand Std Dev | E5: LeadTimeDays | F5: Safety Stocks | G5: Reorder Point | H5: Annual Demand | I5: OrderingCost | J5: UnitCost | K5: HoldingCostPct | L5: EOQ(unit) | M5: StockOnHand | N5: Status
A6: =Raw_Inventory!A2 -> SKU-001 | B6: =Raw_Inventory!B2 -> Wireless Mouse | C6: =Raw_Inventory!L2 -> 15.041096 | D6: =O31 -> 21.589153 | E6: =Raw_Inventory!H2 -> 7 | F6: =ROUND($H$3*D6*SQRT(E6),0) -> 94 | G6: =ROUND(C6*E6+F6,0) -> 199 | H6: =Raw_Inventory!K2 -> 5490 | I6: =Raw_Inventory!I2 -> 658 | J6: =Raw_Inventory!E2 -> 1283.44 | K6: =Raw_Inventory!J2 -> 0.19 | L6: =ROUNDUP(SQRT(2*H6*I6/(J6*K6)),0) -> 173 | M6: =Raw_Inventory!G2 -> 467 | N6: =IF(M6<G6,"Reorder Now","Ok") -> Ok
A7: =Raw_Inventory!A3 -> SKU-002 | B7: =Raw_Inventory!B3 -> Bluetooth Speaker | C7: =Raw_Inventory!L3 -> 8.3616438 | D7: =O32 -> 13.743927 | E7: =Raw_Inventory!H3 -> 13 | F7: =ROUND($H$3*D7*SQRT(E7),0) -> 82 | G7: =ROUND(C7*E7+F7,0) -> 191 | H7: =Raw_Inventory!K3 -> 3052 | I7: =Raw_Inventory!I3 -> 1823 | J7: =Raw_Inventory!E3 -> 972.67 | K7: =Raw_Inventory!J3 -> 0.27 | L7: =ROUNDUP(SQRT(2*H7*I7/(J7*K7)),0) -> 206 | M7: =Raw_Inventory!G3 -> 126 | N7: =IF(M7<G7,"Reorder Now","Ok") -> Reorder Now
A8: =Raw_Inventory!A4 -> SKU-003 | B8: =Raw_Inventory!B4 -> USB-C Charger | C8: =Raw_Inventory!L4 -> 16.808219 | D8: =O33 -> 22.186967 | E8: =Raw_Inventory!H4 -> 7 | F8: =ROUND($H$3*D8*SQRT(E8),0) -> 97 | G8: =ROUND(C8*E8+F8,0) -> 215 | H8: =Raw_Inventory!K4 -> 6135 | I8: =Raw_Inventory!I4 -> 1771 | J8: =Raw_Inventory!E4 -> 1479.01 | K8: =Raw_Inventory!J4 -> 0.2 | L8: =ROUNDUP(SQRT(2*H8*I8/(J8*K8)),0) -> 272 | M8: =Raw_Inventory!G4 -> 544 | N8: =IF(M8<G8,"Reorder Now","Ok") -> Ok
A9: =Raw_Inventory!A5 -> SKU-004 | B9: =Raw_Inventory!B5 -> Cotton T-Shirt | C9: =Raw_Inventory!L5 -> 6.0136986 | D9: =O34 -> 7.0326725 | E9: =Raw_Inventory!H5 -> 5 | F9: =ROUND($H$3*D9*SQRT(E9),0) -> 26 | G9: =ROUND(C9*E9+F9,0) -> 56 | H9: =Raw_Inventory!K5 -> 2195 | I9: =Raw_Inventory!I5 -> 1958 | J9: =Raw_Inventory!E5 -> 605.66 | K9: =Raw_Inventory!J5 -> 0.17 | L9: =ROUNDUP(SQRT(2*H9*I9/(J9*K9)),0) -> 289 | M9: =Raw_Inventory!G5 -> 626 | N9: =IF(M9<G9,"Reorder Now","Ok") -> Ok
A10: =Raw_Inventory!A6 -> SKU-005 | B10: =Raw_Inventory!B6 -> Denim Jacket | C10: =Raw_Inventory!L6 -> 12.912329 | D10: =O35 -> 19.215805 | E10: =Raw_Inventory!H6 -> 5 | F10: =ROUND($H$3*D10*SQRT(E10),0) -> 71 | G10: =ROUND(C10*E10+F10,0) -> 136 | H10: =Raw_Inventory!K6 -> 4713 | I10: =Raw_Inventory!I6 -> 2052 | J10: =Raw_Inventory!E6 -> 618.83 | K10: =Raw_Inventory!J6 -> 0.18 | L10: =ROUNDUP(SQRT(2*H10*I10/(J10*K10)),0) -> 417 | M10: =Raw_Inventory!G6 -> 866 | N10: =IF(M10<G10,"Reorder Now","Ok") -> Ok
A11: =Raw_Inventory!A7 -> SKU-006 | B11: =Raw_Inventory!B7 -> Running Shoes | C11: =Raw_Inventory!L7 -> 6.2958904 | D11: =O36 -> 10.516989 | E11: =Raw_Inventory!H7 -> 5 | F11: =ROUND($H$3*D11*SQRT(E11),0) -> 39 | G11: =ROUND(C11*E11+F11,0) -> 70 | H11: =Raw_Inventory!K7 -> 2298 | I11: =Raw_Inventory!I7 -> 1811 | J11: =Raw_Inventory!E7 -> 125.58 | K11: =Raw_Inventory!J7 -> 0.21 | L11: =ROUNDUP(SQRT(2*H11*I11/(J11*K11)),0) -> 562 | M11: =Raw_Inventory!G7 -> 297 | N11: =IF(M11<G11,"Reorder Now","Ok") -> Ok
A12: =Raw_Inventory!A8 -> SKU-007 | B12: =Raw_Inventory!B8 -> Non-stick Pan | C12: =Raw_Inventory!L8 -> 6.4356164 | D12: =O37 -> 8.5630664 | E12: =Raw_Inventory!H8 -> 4 | F12: =ROUND($H$3*D12*SQRT(E12),0) -> 28 | G12: =ROUND(C12*E12+F12,0) -> 54 | H12: =Raw_Inventory!K8 -> 2349 | I12: =Raw_Inventory!I8 -> 1669 | J12: =Raw_Inventory!E8 -> 1378.66 | K12: =Raw_Inventory!J8 -> 0.28 | L12: =ROUNDUP(SQRT(2*H12*I12/(J12*K12)),0) -> 143 | M12: =Raw_Inventory!G8 -> 844 | N12: =IF(M12<G12,"Reorder Now","Ok") -> Ok
A13: =Raw_Inventory!A9 -> SKU-008 | B13: =Raw_Inventory!B9 -> Air Fryer | C13: =Raw_Inventory!L9 -> 19.693151 | D13: =O38 -> 26.173647 | E13: =Raw_Inventory!H9 -> 15 | F13: =ROUND($H$3*D13*SQRT(E13),0) -> 167 | G13: =ROUND(C13*E13+F13,0) -> 462 | H13: =Raw_Inventory!K9 -> 7188 | I13: =Raw_Inventory!I9 -> 594 | J13: =Raw_Inventory!E9 -> 647.15 | K13: =Raw_Inventory!J9 -> 0.17 | L13: =ROUNDUP(SQRT(2*H13*I13/(J13*K13)),0) -> 279 | M13: =Raw_Inventory!G9 -> 853 | N13: =IF(M13<G13,"Reorder Now","Ok") -> Ok
A14: =Raw_Inventory!A10 -> SKU-009 | B14: =Raw_Inventory!B10 -> LED Lamp | C14: =Raw_Inventory!L10 -> 9.0739726 | D14: =O39 -> 14.45046 | E14: =Raw_Inventory!H10 -> 4 | F14: =ROUND($H$3*D14*SQRT(E14),0) -> 48 | G14: =ROUND(C14*E14+F14,0) -> 84 | H14: =Raw_Inventory!K10 -> 3312 | I14: =Raw_Inventory!I10 -> 1692 | J14: =Raw_Inventory!E10 -> 970.97 | K14: =Raw_Inventory!J10 -> 0.22 | L14: =ROUNDUP(SQRT(2*H14*I14/(J14*K14)),0) -> 230 | M14: =Raw_Inventory!G10 -> 470 | N14: =IF(M14<G14,"Reorder Now","Ok") -> Ok
A15: =Raw_Inventory!A11 -> SKU-010 | B15: =Raw_Inventory!B11 -> Basmati Rice 5kg | C15: =Raw_Inventory!L11 -> 17.909589 | D15: =O40 -> 27.627707 | E15: =Raw_Inventory!H11 -> 6 | F15: =ROUND($H$3*D15*SQRT(E15),0) -> 112 | G15: =ROUND(C15*E15+F15,0) -> 219 | H15: =Raw_Inventory!K11 -> 6537 | I15: =Raw_Inventory!I11 -> 1782 | J15: =Raw_Inventory!E11 -> 437.01 | K15: =Raw_Inventory!J11 -> 0.17 | L15: =ROUNDUP(SQRT(2*H15*I15/(J15*K15)),0) -> 560 | M15: =Raw_Inventory!G11 -> 867 | N15: =IF(M15<G15,"Reorder Now","Ok") -> Ok
A16: =Raw_Inventory!A12 -> SKU-011 | B16: =Raw_Inventory!B12 -> Cooking Oil 1L | C16: =Raw_Inventory!L12 -> 19.416438 | D16: =O41 -> 23.857063 | E16: =Raw_Inventory!H12 -> 6 | F16: =ROUND($H$3*D16*SQRT(E16),0) -> 96 | G16: =ROUND(C16*E16+F16,0) -> 212 | H16: =Raw_Inventory!K12 -> 7087 | I16: =Raw_Inventory!I12 -> 2325 | J16: =Raw_Inventory!E12 -> 697.37 | K16: =Raw_Inventory!J12 -> 0.28 | L16: =ROUNDUP(SQRT(2*H16*I16/(J16*K16)),0) -> 411 | M16: =Raw_Inventory!G12 -> 599 | N16: =IF(M16<G16,"Reorder Now","Ok") -> Ok
A17: =Raw_Inventory!A13 -> SKU-012 | B17: =Raw_Inventory!B13 -> Green Tea Pack | C17: =Raw_Inventory!L13 -> 11.958904 | D17: =O42 -> 18.247882 | E17: =Raw_Inventory!H13 -> 6 | F17: =ROUND($H$3*D17*SQRT(E17),0) -> 74 | G17: =ROUND(C17*E17+F17,0) -> 146 | H17: =Raw_Inventory!K13 -> 4365 | I17: =Raw_Inventory!I13 -> 823 | J17: =Raw_Inventory!E13 -> 503.79 | K17: =Raw_Inventory!J13 -> 0.29 | L17: =ROUNDUP(SQRT(2*H17*I17/(J17*K17)),0) -> 222 | M17: =Raw_Inventory!G13 -> 860 | N17: =IF(M17<G17,"Reorder Now","Ok") -> Ok
... A20: =Raw_Inventory!A16 -> SKU-015 | B20: =Raw_Inventory!B16 -> Football | C20: =Raw_Inventory!L16 -> 3.9972603 | D20: =O45 -> 5.5925544 | E20: =Raw_Inventory!H16 -> 13 | F20: =ROUND($H$3*D20*SQRT(E20),0) -> 33 | G20: =ROUND(C20*E20+F20,0) -> 85 | H20: =Raw_Inventory!K16 -> 1459 | I20: =Raw_Inventory!I16 -> 1555 | J20: =Raw_Inventory!E16 -> 1160.06 | K20: =Raw_Inventory!J16 -> 0.24 | L20: =ROUNDUP(SQRT(2*H20*I20/(J20*K20)),0) -> 128 | M20: =Raw_Inventory!G16 -> 351 | N20: =IF(M20<G20,"Reorder Now","Ok") -> Ok
A22: Safety Stock = Z-Score *Demand StdDev *rooth(Lead Time) => Buffer stock to absorb demand Variability during replacement.
A23: Reorder Point = (Avg Daily Demand * Lead Time) + Safety Stock => The stock level that triggers new purchase order
A24: EOQ = Rooth ((2*Annual Demand * Ordering Cost %) / (Unit Cost * Holding Cost %) => The ordering quantity that minimises total ordering + holding cost
A25: Demand Std Dev = STDEV of 12 real monthly demand totals per SKU(see supporting table below ), scaled to a daily-equivalent by / rooth 30.4h
A28: Supporting Calculation - Monthly Demand History Per SKU (2025 actual from Raw Orders)
A29: Demand std Dev feeding the planner above is STDEV of these 12 real monthly totals, cinverted to a daily-equivalent figure - Nothing here is assumed hal
A30: SKU | B30: Jan | C30: Feb | D30: Mar | E30: Apr | F30: May | G30: Jun | H30: Jul | I30: Aug | J30: Sep | K30: Oct | L30: Nov | M30: Dec | N30: Monthly std Dev | O30: Daily Std Dev
A31: =Raw_Inventory!A2 -> SKU-001 | B31: =SUMIFS(Raw_Orders!$H:$H,Raw_Orders!$E:$E,'Reorder EOQ Planner '!A31,Raw_Orders!$B:$B,">="&DATE(2025,1,1),Raw_Orders!$B:$B,"<="&EOMONTH(DATE(2025,1,1),0)) -> 556 | C31: =SUMIFS(Raw_Orders!$H:$H,Raw_Orders!$E:$E,'Reorder EOQ Planner '!A31,Raw_Orders!$B:$B,">="&DATE(2025,2,1),Raw_Orders!$B:$B,"<="&EOMONTH(DATE(2025,2,1),0)) -> 449 | D31: =SUMIFS(Raw_Orders!$H:$H,Raw_Orders!$E:$E,'Reorder EOQ Planner '!A31,Raw_Orders!$B:$B,">="&DATE(2025,3,1),Raw_Orders!$B:$B,"<="&EOMONTH(DATE(2025,3,1),0)) -> 516 | E31: =SUMIFS(Raw_Orders!$H:$H,Raw_Orders!$E:$E,'Reorder EOQ Planner '!$A31,Raw_Orders!$B:$B,">="&DATE(2025,4,1),Raw_Orders!$B:$B,"<="&EOMONTH(DATE(2025,4,1),0)) -> 311 | F31: =SUMIFS(Raw_Orders!$H:$H,Raw_Orders!$E:$E,'Reorder EOQ Planner '!$A31,Raw_Orders!$B:$B,">="&DATE(2025,5,1),Raw_Orders!$B:$B,"<="&EOMONTH(DATE(2025,5,1),0)) -> 509 | G31: =SUMIFS(Raw_Orders!$H:$H,Raw_Orders!$E:$E,'Reorder EOQ Planner '!$A31,Raw_Orders!$B:$B,">="&DATE(2025,6,1),Raw_Orders!$B:$B,"<="&EOMONTH(DATE(2025,6,1),0)) -> 312 | H31: =SUMIFS(Raw_Orders!$H:$H,Raw_Orders!$E:$E,'Reorder EOQ Planner '!$A31,Raw_Orders!$B:$B,">="&DATE(2025,7,1),Raw_Orders!$B:$B,"<="&EOMONTH(DATE(2025,7,1),0)) -> 396 | I31: =SUMIFS(Raw_Orders!$H:$H,Raw_Orders!$E:$E,'Reorder EOQ Planner '!$A31,Raw_Orders!$B:$B,">="&DATE(2025,8,1),Raw_Orders!$B:$B,"<="&EOMONTH(DATE(2025,8,1),0)) -> 557 | J31: =SUMIFS(Raw_Orders!$H:$H,Raw_Orders!$E:$E,'Reorder EOQ Planner '!$A31,Raw_Orders!$B:$B,">="&DATE(2025,9,1),Raw_Orders!$B:$B,"<="&EOMONTH(DATE(2025,9,1),0)) -> 401 | K31: =SUMIFS(Raw_Orders!$H:$H,Raw_Orders!$E:$E,'Reorder EOQ Planner '!$A31,Raw_Orders!$B:$B,">="&DATE(2025,10,1),Raw_Orders!$B:$B,"<="&EOMONTH(DATE(2025,10,1),0)) -> 363 | L31: =SUMIFS(Raw_Orders!$H:$H,Raw_Orders!$E:$E,'Reorder EOQ Planner '!$A31,Raw_Orders!$B:$B,">="&DATE(2025,11,1),Raw_Orders!$B:$B,"<="&EOMONTH(DATE(2025,11,1),0)) -> 401 | M31: =SUMIFS(Raw_Orders!$H:$H,Raw_Orders!$E:$E,'Reorder EOQ Planner '!$A31,Raw_Orders!$B:$B,">="&DATE(2025,12,1),Raw_Orders!$B:$B,"<="&EOMONTH(DATE(2025,12,1),0)) -> 719 | N31: =STDEV(B31:M31) -> 119.03437 | O31: =N31/SQRT(30.4) -> 21.589153
A32: =Raw_Inventory!A3 -> SKU-002 | B32: =SUMIFS(Raw_Orders!$H:$H,Raw_Orders!$E:$E,'Reorder EOQ Planner '!A32,Raw_Orders!$B:$B,">="&DATE(2025,1,1),Raw_Orders!$B:$B,"<="&EOMONTH(DATE(2025,1,1),0)) -> 139 | C32: =SUMIFS(Raw_Orders!$H:$H,Raw_Orders!$E:$E,'Reorder EOQ Planner '!A32,Raw_Orders!$B:$B,">="&DATE(2025,2,1),Raw_Orders!$B:$B,"<="&EOMONTH(DATE(2025,2,1),0)) -> 187 | D32: =SUMIFS(Raw_Orders!$H:$H,Raw_Orders!$E:$E,'Reorder EOQ Planner '!A32,Raw_Orders!$B:$B,">="&DATE(2025,3,1),Raw_Orders!$B:$B,"<="&EOMONTH(DATE(2025,3,1),0)) -> 193 | E32: =SUMIFS(Raw_Orders!$H:$H,Raw_Orders!$E:$E,'Reorder EOQ Planner '!$A32,Raw_Orders!$B:$B,">="&DATE(2025,4,1),Raw_Orders!$B:$B,"<="&EOMONTH(DATE(2025,4,1),0)) -> 212 | F32: =SUMIFS(Raw_Orders!$H:$H,Raw_Orders!$E:$E,'Reorder EOQ Planner '!$A32,Raw_Orders!$B:$B,">="&DATE(2025,5,1),Raw_Orders!$B:$B,"<="&EOMONTH(DATE(2025,5,1),0)) -> 237 | G32: =SUMIFS(Raw_Orders!$H:$H,Raw_Orders!$E:$E,'Reorder EOQ Planner '!$A32,Raw_Orders!$B:$B,">="&DATE(2025,6,1),Raw_Orders!$B:$B,"<="&EOMONTH(DATE(2025,6,1),0)) -> 194 | H32: =SUMIFS(Raw_Orders!$H:$H,Raw_Orders!$E:$E,'Reorder EOQ Planner '!$A32,Raw_Orders!$B:$B,">="&DATE(2025,7,1),Raw_Orders!$B:$B,"<="&EOMONTH(DATE(2025,7,1),0)) -> 307 | I32: =SUMIFS(Raw_Orders!$H:$H,Raw_Orders!$E:$E,'Reorder EOQ Planner '!$A32,Raw_Orders!$B:$B,">="&DATE(2025,8,1),Raw_Orders!$B:$B,"<="&EOMONTH(DATE(2025,8,1),0)) -> 290 | J32: =SUMIFS(Raw_Orders!$H:$H,Raw_Orders!$E:$E,'Reorder EOQ Planner '!$A32,Raw_Orders!$B:$B,">="&DATE(2025,9,1),Raw_Orders!$B:$B,"<="&EOMONTH(DATE(2025,9,1),0)) -> 271 | K32: =SUMIFS(Raw_Orders!$H:$H,Raw_Orders!$E:$E,'Reorder EOQ Planner '!$A32,Raw_Orders!$B:$B,">="&DATE(2025,10,1),Raw_Orders!$B:$B,"<="&EOMONTH(DATE(2025,10,1),0)) -> 400 | L32: =SUMIFS(Raw_Orders!$H:$H,Raw_Orders!$E:$E,'Reorder EOQ Planner '!$A32,Raw_Orders!$B:$B,">="&DATE(2025,11,1),Raw_Orders!$B:$B,"<="&EOMONTH(DATE(2025,11,1),0)) -> 355 | M32: =SUMIFS(Raw_Orders!$H:$H,Raw_Orders!$E:$E,'Reorder EOQ Planner '!$A32,Raw_Orders!$B:$B,">="&DATE(2025,12,1),Raw_Orders!$B:$B,"<="&EOMONTH(DATE(2025,12,1),0)) -> 267 | N32: =STDEV(B32:M32) -> 75.778785 | O32: =N32/SQRT(30.4) -> 13.743927
A33: =Raw_Inventory!A4 -> SKU-003 | B33: =SUMIFS(Raw_Orders!$H:$H,Raw_Orders!$E:$E,'Reorder EOQ Planner '!A33,Raw_Orders!$B:$B,">="&DATE(2025,1,1),Raw_Orders!$B:$B,"<="&EOMONTH(DATE(2025,1,1),0)) -> 486 | C33: =SUMIFS(Raw_Orders!$H:$H,Raw_Orders!$E:$E,'Reorder EOQ Planner '!A33,Raw_Orders!$B:$B,">="&DATE(2025,2,1),Raw_Orders!$B:$B,"<="&EOMONTH(DATE(2025,2,1),0)) -> 421 | D33: =SUMIFS(Raw_Orders!$H:$H,Raw_Orders!$E:$E,'Reorder EOQ Planner '!A33,Raw_Orders!$B:$B,">="&DATE(2025,3,1),Raw_Orders!$B:$B,"<="&EOMONTH(DATE(2025,3,1),0)) -> 623 | E33: =SUMIFS(Raw_Orders!$H:$H,Raw_Orders!$E:$E,'Reorder EOQ Planner '!$A33,Raw_Orders!$B:$B,">="&DATE(2025,4,1),Raw_Orders!$B:$B,"<="&EOMONTH(DATE(2025,4,1),0)) -> 414 | F33: =SUMIFS(Raw_Orders!$H:$H,Raw_Orders!$E:$E,'Reorder EOQ Planner '!$A33,Raw_Orders!$B:$B,">="&DATE(2025,5,1),Raw_Orders!$B:$B,"<="&EOMONTH(DATE(2025,5,1),0)) -> 564 | G33: =SUMIFS(Raw_Orders!$H:$H,Raw_Orders!$E:$E,'Reorder EOQ Planner '!$A33,Raw_Orders!$B:$B,">="&DATE(2025,6,1),Raw_Orders!$B:$B,"<="&EOMONTH(DATE(2025,6,1),0)) -> 364 | H33: =SUMIFS(Raw_Orders!$H:$H,Raw_Orders!$E:$E,'Reorder EOQ Planner '!$A33,Raw_Orders!$B:$B,">="&DATE(2025,7,1),Raw_Orders!$B:$B,"<="&EOMONTH(DATE(2025,7,1),0)) -> 554 | I33: =SUMIFS(Raw_Orders!$H:$H,Raw_Orders!$E:$E,'Reorder EOQ Planner '!$A33,Raw_Orders!$B:$B,">="&DATE(2025,8,1),Raw_Orders!$B:$B,"<="&EOMONTH(DATE(2025,8,1),0)) -> 379 | J33: =SUMIFS(Raw_Orders!$H:$H,Raw_Orders!$E:$E,'Reorder EOQ Planner '!$A33,Raw_Orders!$B:$B,">="&DATE(2025,9,1),Raw_Orders!$B:$B,"<="&EOMONTH(DATE(2025,9,1),0)) -> 584 | K33: =SUMIFS(Raw_Orders!$H:$H,Raw_Orders!$E:$E,'Reorder EOQ Planner '!$A33,Raw_Orders!$B:$B,">="&DATE(2025,10,1),Raw_Orders!$B:$B,"<="&EOMONTH(DATE(2025,10,1),0)) -> 406 | L33: =SUMIFS(Raw_Orders!$H:$H,Raw_Orders!$E:$E,'Reorder EOQ Planner '!$A33,Raw_Orders!$B:$B,">="&DATE(2025,11,1),Raw_Orders!$B:$B,"<="&EOMONTH(DATE(2025,11,1),0)) -> 562 | M33: =SUMIFS(Raw_Orders!$H:$H,Raw_Orders!$E:$E,'Reorder EOQ Planner '!$A33,Raw_Orders!$B:$B,">="&DATE(2025,12,1),Raw_Orders!$B:$B,"<="&EOMONTH(DATE(2025,12,1),0)) -> 778 | N33: =STDEV(B33:M33) -> 122.33049 | O33: =N33/SQRT(30.4) -> 22.186967
A34: =Raw_Inventory!A5 -> SKU-004 | B34: =SUMIFS(Raw_Orders!$H:$H,Raw_Orders!$E:$E,'Reorder EOQ Planner '!A34,Raw_Orders!$B:$B,">="&DATE(2025,1,1),Raw_Orders!$B:$B,"<="&EOMONTH(DATE(2025,1,1),0)) -> 190 | C34: =SUMIFS(Raw_Orders!$H:$H,Raw_Orders!$E:$E,'Reorder EOQ Planner '!A34,Raw_Orders!$B:$B,">="&DATE(2025,2,1),Raw_Orders!$B:$B,"<="&EOMONTH(DATE(2025,2,1),0)) -> 194 | D34: =SUMIFS(Raw_Orders!$H:$H,Raw_Orders!$E:$E,'Reorder EOQ Planner '!A34,Raw_Orders!$B:$B,">="&DATE(2025,3,1),Raw_Orders!$B:$B,"<="&EOMONTH(DATE(2025,3,1),0)) -> 240 | E34: =SUMIFS(Raw_Orders!$H:$H,Raw_Orders!$E:$E,'Reorder EOQ Planner '!$A34,Raw_Orders!$B:$B,">="&DATE(2025,4,1),Raw_Orders!$B:$B,"<="&EOMONTH(DATE(2025,4,1),0)) -> 121 | F34: =SUMIFS(Raw_Orders!$H:$H,Raw_Orders!$E:$E,'Reorder EOQ Planner '!$A34,Raw_Orders!$B:$B,">="&DATE(2025,5,1),Raw_Orders!$B:$B,"<="&EOMONTH(DATE(2025,5,1),0)) -> 208 | G34: =SUMIFS(Raw_Orders!$H:$H,Raw_Orders!$E:$E,'Reorder EOQ Planner '!$A34,Raw_Orders!$B:$B,">="&DATE(2025,6,1),Raw_Orders!$B:$B,"<="&EOMONTH(DATE(2025,6,1),0)) -> 169 | H34: =SUMIFS(Raw_Orders!$H:$H,Raw_Orders!$E:$E,'Reorder EOQ Planner '!$A34,Raw_Orders!$B:$B,">="&DATE(2025,7,1),Raw_Orders!$B:$B,"<="&EOMONTH(DATE(2025,7,1),0)) -> 185 | I34: =SUMIFS(Raw_Orders!$H:$H,Raw_Orders!$E:$E,'Reorder EOQ Planner '!$A34,Raw_Orders!$B:$B,">="&DATE(2025,8,1),Raw_Orders!$B:$B,"<="&EOMONTH(DATE(2025,8,1),0)) -> 158 | J34: =SUMIFS(Raw_Orders!$H:$H,Raw_Orders!$E:$E,'Reorder EOQ Planner '!$A34,Raw_Orders!$B:$B,">="&DATE(2025,9,1),Raw_Orders!$B:$B,"<="&EOMONTH(DATE(2025,9,1),0)) -> 147 | K34: =SUMIFS(Raw_Orders!$H:$H,Raw_Orders!$E:$E,'Reorder EOQ Planner '!$A34,Raw_Orders!$B:$B,">="&DATE(2025,10,1),Raw_Orders!$B:$B,"<="&EOMONTH(DATE(2025,10,1),0)) -> 206 | L34: =SUMIFS(Raw_Orders!$H:$H,Raw_Orders!$E:$E,'Reorder EOQ Planner '!$A34,Raw_Orders!$B:$B,">="&DATE(2025,11,1),Raw_Orders!$B:$B,"<="&EOMONTH(DATE(2025,11,1),0)) -> 134 | M34: =SUMIFS(Raw_Orders!$H:$H,Raw_Orders!$E:$E,'Reorder EOQ Planner '!$A34,Raw_Orders!$B:$B,">="&DATE(2025,12,1),Raw_Orders!$B:$B,"<="&EOMONTH(DATE(2025,12,1),0)) -> 243 | N34: =STDEV(B34:M34) -> 38.77548 | O34: =N34/SQRT(30.4) -> 7.0326725
A35: =Raw_Inventory!A6 -> SKU-005 | B35: =SUMIFS(Raw_Orders!$H:$H,Raw_Orders!$E:$E,'Reorder EOQ Planner '!A35,Raw_Orders!$B:$B,">="&DATE(2025,1,1),Raw_Orders!$B:$B,"<="&EOMONTH(DATE(2025,1,1),0)) -> 362 | C35: =SUMIFS(Raw_Orders!$H:$H,Raw_Orders!$E:$E,'Reorder EOQ Planner '!A35,Raw_Orders!$B:$B,">="&DATE(2025,2,1),Raw_Orders!$B:$B,"<="&EOMONTH(DATE(2025,2,1),0)) -> 272 | D35: =SUMIFS(Raw_Orders!$H:$H,Raw_Orders!$E:$E,'Reorder EOQ Planner '!A35,Raw_Orders!$B:$B,">="&DATE(2025,3,1),Raw_Orders!$B:$B,"<="&EOMONTH(DATE(2025,3,1),0)) -> 285 | E35: =SUMIFS(Raw_Orders!$H:$H,Raw_Orders!$E:$E,'Reorder EOQ Planner '!$A35,Raw_Orders!$B:$B,">="&DATE(2025,4,1),Raw_Orders!$B:$B,"<="&EOMONTH(DATE(2025,4,1),0)) -> 300 | F35: =SUMIFS(Raw_Orders!$H:$H,Raw_Orders!$E:$E,'Reorder EOQ Planner '!$A35,Raw_Orders!$B:$B,">="&DATE(2025,5,1),Raw_Orders!$B:$B,"<="&EOMONTH(DATE(2025,5,1),0)) -> 434 | G35: =SUMIFS(Raw_Orders!$H:$H,Raw_Orders!$E:$E,'Reorder EOQ Planner '!$A35,Raw_Orders!$B:$B,">="&DATE(2025,6,1),Raw_Orders!$B:$B,"<="&EOMONTH(DATE(2025,6,1),0)) -> 278 | H35: =SUMIFS(Raw_Orders!$H:$H,Raw_Orders!$E:$E,'Reorder EOQ Planner '!$A35,Raw_Orders!$B:$B,">="&DATE(2025,7,1),Raw_Orders!$B:$B,"<="&EOMONTH(DATE(2025,7,1),0)) -> 416 | I35: =SUMIFS(Raw_Orders!$H:$H,Raw_Orders!$E:$E,'Reorder EOQ Planner '!$A35,Raw_Orders!$B:$B,">="&DATE(2025,8,1),Raw_Orders!$B:$B,"<="&EOMONTH(DATE(2025,8,1),0)) -> 587 | J35: =SUMIFS(Raw_Orders!$H:$H,Raw_Orders!$E:$E,'Reorder EOQ Planner '!$A35,Raw_Orders!$B:$B,">="&DATE(2025,9,1),Raw_Orders!$B:$B,"<="&EOMONTH(DATE(2025,9,1),0)) -> 378 | K35: =SUMIFS(Raw_Orders!$H:$H,Raw_Orders!$E:$E,'Reorder EOQ Planner '!$A35,Raw_Orders!$B:$B,">="&DATE(2025,10,1),Raw_Orders!$B:$B,"<="&EOMONTH(DATE(2025,10,1),0)) -> 572 | L35: =SUMIFS(Raw_Orders!$H:$H,Raw_Orders!$E:$E,'Reorder EOQ Planner '!$A35,Raw_Orders!$B:$B,">="&DATE(2025,11,1),Raw_Orders!$B:$B,"<="&EOMONTH(DATE(2025,11,1),0)) -> 440 | M35: =SUMIFS(Raw_Orders!$H:$H,Raw_Orders!$E:$E,'Reorder EOQ Planner '!$A35,Raw_Orders!$B:$B,">="&DATE(2025,12,1),Raw_Orders!$B:$B,"<="&EOMONTH(DATE(2025,12,1),0)) -> 389 | N35: =STDEV(B35:M35) -> 105.94864 | O35: =N35/SQRT(30.4) -> 19.215805
A36: =Raw_Inventory!A7 -> SKU-006 | B36: =SUMIFS(Raw_Orders!$H:$H,Raw_Orders!$E:$E,'Reorder EOQ Planner '!A36,Raw_Orders!$B:$B,">="&DATE(2025,1,1),Raw_Orders!$B:$B,"<="&EOMONTH(DATE(2025,1,1),0)) -> 161 | C36: =SUMIFS(Raw_Orders!$H:$H,Raw_Orders!$E:$E,'Reorder EOQ Planner '!A36,Raw_Orders!$B:$B,">="&DATE(2025,2,1),Raw_Orders!$B:$B,"<="&EOMONTH(DATE(2025,2,1),0)) -> 184 | D36: =SUMIFS(Raw_Orders!$H:$H,Raw_Orders!$E:$E,'Reorder EOQ Planner '!A36,Raw_Orders!$B:$B,">="&DATE(2025,3,1),Raw_Orders!$B:$B,"<="&EOMONTH(DATE(2025,3,1),0)) -> 145 | E36: =SUMIFS(Raw_Orders!$H:$H,Raw_Orders!$E:$E,'Reorder EOQ Planner '!$A36,Raw_Orders!$B:$B,">="&DATE(2025,4,1),Raw_Orders!$B:$B,"<="&EOMONTH(DATE(2025,4,1),0)) -> 134 | F36: =SUMIFS(Raw_Orders!$H:$H,Raw_Orders!$E:$E,'Reorder EOQ Planner '!$A36,Raw_Orders!$B:$B,">="&DATE(2025,5,1),Raw_Orders!$B:$B,"<="&EOMONTH(DATE(2025,5,1),0)) -> 257 | G36: =SUMIFS(Raw_Orders!$H:$H,Raw_Orders!$E:$E,'Reorder EOQ Planner '!$A36,Raw_Orders!$B:$B,">="&DATE(2025,6,1),Raw_Orders!$B:$B,"<="&EOMONTH(DATE(2025,6,1),0)) -> 205 | H36: =SUMIFS(Raw_Orders!$H:$H,Raw_Orders!$E:$E,'Reorder EOQ Planner '!$A36,Raw_Orders!$B:$B,">="&DATE(2025,7,1),Raw_Orders!$B:$B,"<="&EOMONTH(DATE(2025,7,1),0)) -> 224 | I36: =SUMIFS(Raw_Orders!$H:$H,Raw_Orders!$E:$E,'Reorder EOQ Planner '!$A36,Raw_Orders!$B:$B,">="&DATE(2025,8,1),Raw_Orders!$B:$B,"<="&EOMONTH(DATE(2025,8,1),0)) -> 185 | J36: =SUMIFS(Raw_Orders!$H:$H,Raw_Orders!$E:$E,'Reorder EOQ Planner '!$A36,Raw_Orders!$B:$B,">="&DATE(2025,9,1),Raw_Orders!$B:$B,"<="&EOMONTH(DATE(2025,9,1),0)) -> 76 | K36: =SUMIFS(Raw_Orders!$H:$H,Raw_Orders!$E:$E,'Reorder EOQ Planner '!$A36,Raw_Orders!$B:$B,">="&DATE(2025,10,1),Raw_Orders!$B:$B,"<="&EOMONTH(DATE(2025,10,1),0)) -> 280 | L36: =SUMIFS(Raw_Orders!$H:$H,Raw_Orders!$E:$E,'Reorder EOQ Planner '!$A36,Raw_Orders!$B:$B,">="&DATE(2025,11,1),Raw_Orders!$B:$B,"<="&EOMONTH(DATE(2025,11,1),0)) -> 253 | M36: =SUMIFS(Raw_Orders!$H:$H,Raw_Orders!$E:$E,'Reorder EOQ Planner '!$A36,Raw_Orders!$B:$B,">="&DATE(2025,12,1),Raw_Orders!$B:$B,"<="&EOMONTH(DATE(2025,12,1),0)) -> 194 | N36: =STDEV(B36:M36) -> 57.986676 | O36: =N36/SQRT(30.4) -> 10.516989
A37: =Raw_Inventory!A8 -> SKU-007 | B37: =SUMIFS(Raw_Orders!$H:$H,Raw_Orders!$E:$E,'Reorder EOQ Planner '!A37,Raw_Orders!$B:$B,">="&DATE(2025,1,1),Raw_Orders!$B:$B,"<="&EOMONTH(DATE(2025,1,1),0)) -> 157 | C37: =SUMIFS(Raw_Orders!$H:$H,Raw_Orders!$E:$E,'Reorder EOQ Planner '!A37,Raw_Orders!$B:$B,">="&DATE(2025,2,1),Raw_Orders!$B:$B,"<="&EOMONTH(DATE(2025,2,1),0)) -> 169 | D37: =SUMIFS(Raw_Orders!$H:$H,Raw_Orders!$E:$E,'Reorder EOQ Planner '!A37,Raw_Orders!$B:$B,">="&DATE(2025,3,1),Raw_Orders!$B:$B,"<="&EOMONTH(DATE(2025,3,1),0)) -> 156 | E37: =SUMIFS(Raw_Orders!$H:$H,Raw_Orders!$E:$E,'Reorder EOQ Planner '!$A37,Raw_Orders!$B:$B,">="&DATE(2025,4,1),Raw_Orders!$B:$B,"<="&EOMONTH(DATE(2025,4,1),0)) -> 182 | F37: =SUMIFS(Raw_Orders!$H:$H,Raw_Orders!$E:$E,'Reorder EOQ Planner '!$A37,Raw_Orders!$B:$B,">="&DATE(2025,5,1),Raw_Orders!$B:$B,"<="&EOMONTH(DATE(2025,5,1),0)) -> 208 | G37: =SUMIFS(Raw_Orders!$H:$H,Raw_Orders!$E:$E,'Reorder EOQ Planner '!$A37,Raw_Orders!$B:$B,">="&DATE(2025,6,1),Raw_Orders!$B:$B,"<="&EOMONTH(DATE(2025,6,1),0)) -> 217 | H37: =SUMIFS(Raw_Orders!$H:$H,Raw_Orders!$E:$E,'Reorder EOQ Planner '!$A37,Raw_Orders!$B:$B,">="&DATE(2025,7,1),Raw_Orders!$B:$B,"<="&EOMONTH(DATE(2025,7,1),0)) -> 133 | I37: =SUMIFS(Raw_Orders!$H:$H,Raw_Orders!$E:$E,'Reorder EOQ Planner '!$A37,Raw_Orders!$B:$B,">="&DATE(2025,8,1),Raw_Orders!$B:$B,"<="&EOMONTH(DATE(2025,8,1),0)) -> 154 | J37: =SUMIFS(Raw_Orders!$H:$H,Raw_Orders!$E:$E,'Reorder EOQ Planner '!$A37,Raw_Orders!$B:$B,">="&DATE(2025,9,1),Raw_Orders!$B:$B,"<="&EOMONTH(DATE(2025,9,1),0)) -> 199 | K37: =SUMIFS(Raw_Orders!$H:$H,Raw_Orders!$E:$E,'Reorder EOQ Planner '!$A37,Raw_Orders!$B:$B,">="&DATE(2025,10,1),Raw_Orders!$B:$B,"<="&EOMONTH(DATE(2025,10,1),0)) -> 296 | L37: =SUMIFS(Raw_Orders!$H:$H,Raw_Orders!$E:$E,'Reorder EOQ Planner '!$A37,Raw_Orders!$B:$B,">="&DATE(2025,11,1),Raw_Orders!$B:$B,"<="&EOMONTH(DATE(2025,11,1),0)) -> 254 | M37: =SUMIFS(Raw_Orders!$H:$H,Raw_Orders!$E:$E,'Reorder EOQ Planner '!$A37,Raw_Orders!$B:$B,">="&DATE(2025,12,1),Raw_Orders!$B:$B,"<="&EOMONTH(DATE(2025,12,1),0)) -> 224 | N37: =STDEV(B37:M37) -> 47.21349 | O37: =N37/SQRT(30.4) -> 8.5630664
A38: =Raw_Inventory!A9 -> SKU-008 | B38: =SUMIFS(Raw_Orders!$H:$H,Raw_Orders!$E:$E,'Reorder EOQ Planner '!A38,Raw_Orders!$B:$B,">="&DATE(2025,1,1),Raw_Orders!$B:$B,"<="&EOMONTH(DATE(2025,1,1),0)) -> 404 | C38: =SUMIFS(Raw_Orders!$H:$H,Raw_Orders!$E:$E,'Reorder EOQ Planner '!A38,Raw_Orders!$B:$B,">="&DATE(2025,2,1),Raw_Orders!$B:$B,"<="&EOMONTH(DATE(2025,2,1),0)) -> 525 | D38: =SUMIFS(Raw_Orders!$H:$H,Raw_Orders!$E:$E,'Reorder EOQ Planner '!A38,Raw_Orders!$B:$B,">="&DATE(2025,3,1),Raw_Orders!$B:$B,"<="&EOMONTH(DATE(2025,3,1),0)) -> 682 | E38: =SUMIFS(Raw_Orders!$H:$H,Raw_Orders!$E:$E,'Reorder EOQ Planner '!$A38,Raw_Orders!$B:$B,">="&DATE(2025,4,1),Raw_Orders!$B:$B,"<="&EOMONTH(DATE(2025,4,1),0)) -> 494 | F38: =SUMIFS(Raw_Orders!$H:$H,Raw_Orders!$E:$E,'Reorder EOQ Planner '!$A38,Raw_Orders!$B:$B,">="&DATE(2025,5,1),Raw_Orders!$B:$B,"<="&EOMONTH(DATE(2025,5,1),0)) -> 463 | G38: =SUMIFS(Raw_Orders!$H:$H,Raw_Orders!$E:$E,'Reorder EOQ Planner '!$A38,Raw_Orders!$B:$B,">="&DATE(2025,6,1),Raw_Orders!$B:$B,"<="&EOMONTH(DATE(2025,6,1),0)) -> 432 | H38: =SUMIFS(Raw_Orders!$H:$H,Raw_Orders!$E:$E,'Reorder EOQ Planner '!$A38,Raw_Orders!$B:$B,">="&DATE(2025,7,1),Raw_Orders!$B:$B,"<="&EOMONTH(DATE(2025,7,1),0)) -> 566 | I38: =SUMIFS(Raw_Orders!$H:$H,Raw_Orders!$E:$E,'Reorder EOQ Planner '!$A38,Raw_Orders!$B:$B,">="&DATE(2025,8,1),Raw_Orders!$B:$B,"<="&EOMONTH(DATE(2025,8,1),0)) -> 793 | J38: =SUMIFS(Raw_Orders!$H:$H,Raw_Orders!$E:$E,'Reorder EOQ Planner '!$A38,Raw_Orders!$B:$B,">="&DATE(2025,9,1),Raw_Orders!$B:$B,"<="&EOMONTH(DATE(2025,9,1),0)) -> 652 | K38: =SUMIFS(Raw_Orders!$H:$H,Raw_Orders!$E:$E,'Reorder EOQ Planner '!$A38,Raw_Orders!$B:$B,">="&DATE(2025,10,1),Raw_Orders!$B:$B,"<="&EOMONTH(DATE(2025,10,1),0)) -> 824 | L38: =SUMIFS(Raw_Orders!$H:$H,Raw_Orders!$E:$E,'Reorder EOQ Planner '!$A38,Raw_Orders!$B:$B,">="&DATE(2025,11,1),Raw_Orders!$B:$B,"<="&EOMONTH(DATE(2025,11,1),0)) -> 769 | M38: =SUMIFS(Raw_Orders!$H:$H,Raw_Orders!$E:$E,'Reorder EOQ Planner '!$A38,Raw_Orders!$B:$B,">="&DATE(2025,12,1),Raw_Orders!$B:$B,"<="&EOMONTH(DATE(2025,12,1),0)) -> 584 | N38: =STDEV(B38:M38) -> 144.31153 | O38: =N38/SQRT(30.4) -> 26.173647
A39: =Raw_Inventory!A10 -> SKU-009 | B39: =SUMIFS(Raw_Orders!$H:$H,Raw_Orders!$E:$E,'Reorder EOQ Planner '!A39,Raw_Orders!$B:$B,">="&DATE(2025,1,1),Raw_Orders!$B:$B,"<="&EOMONTH(DATE(2025,1,1),0)) -> 238 | C39: =SUMIFS(Raw_Orders!$H:$H,Raw_Orders!$E:$E,'Reorder EOQ Planner '!A39,Raw_Orders!$B:$B,">="&DATE(2025,2,1),Raw_Orders!$B:$B,"<="&EOMONTH(DATE(2025,2,1),0)) -> 280 | D39: =SUMIFS(Raw_Orders!$H:$H,Raw_Orders!$E:$E,'Reorder EOQ Planner '!A39,Raw_Orders!$B:$B,">="&DATE(2025,3,1),Raw_Orders!$B:$B,"<="&EOMONTH(DATE(2025,3,1),0)) -> 253 | E39: =SUMIFS(Raw_Orders!$H:$H,Raw_Orders!$E:$E,'Reorder EOQ Planner '!$A39,Raw_Orders!$B:$B,">="&DATE(2025,4,1),Raw_Orders!$B:$B,"<="&EOMONTH(DATE(2025,4,1),0)) -> 119 | F39: =SUMIFS(Raw_Orders!$H:$H,Raw_Orders!$E:$E,'Reorder EOQ Planner '!$A39,Raw_Orders!$B:$B,">="&DATE(2025,5,1),Raw_Orders!$B:$B,"<="&EOMONTH(DATE(2025,5,1),0)) -> 256 | G39: =SUMIFS(Raw_Orders!$H:$H,Raw_Orders!$E:$E,'Reorder EOQ Planner '!$A39,Raw_Orders!$B:$B,">="&DATE(2025,6,1),Raw_Orders!$B:$B,"<="&EOMONTH(DATE(2025,6,1),0)) -> 241 | H39: =SUMIFS(Raw_Orders!$H:$H,Raw_Orders!$E:$E,'Reorder EOQ Planner '!$A39,Raw_Orders!$B:$B,">="&DATE(2025,7,1),Raw_Orders!$B:$B,"<="&EOMONTH(DATE(2025,7,1),0)) -> 310 | I39: =SUMIFS(Raw_Orders!$H:$H,Raw_Orders!$E:$E,'Reorder EOQ Planner '!$A39,Raw_Orders!$B:$B,">="&DATE(2025,8,1),Raw_Orders!$B:$B,"<="&EOMONTH(DATE(2025,8,1),0)) -> 298 | J39: =SUMIFS(Raw_Orders!$H:$H,Raw_Orders!$E:$E,'Reorder EOQ Planner '!$A39,Raw_Orders!$B:$B,">="&DATE(2025,9,1),Raw_Orders!$B:$B,"<="&EOMONTH(DATE(2025,9,1),0)) -> 235 | K39: =SUMIFS(Raw_Orders!$H:$H,Raw_Orders!$E:$E,'Reorder EOQ Planner '!$A39,Raw_Orders!$B:$B,">="&DATE(2025,10,1),Raw_Orders!$B:$B,"<="&EOMONTH(DATE(2025,10,1),0)) -> 464 | L39: =SUMIFS(Raw_Orders!$H:$H,Raw_Orders!$E:$E,'Reorder EOQ Planner '!$A39,Raw_Orders!$B:$B,">="&DATE(2025,11,1),Raw_Orders!$B:$B,"<="&EOMONTH(DATE(2025,11,1),0)) -> 328 | M39: =SUMIFS(Raw_Orders!$H:$H,Raw_Orders!$E:$E,'Reorder EOQ Planner '!$A39,Raw_Orders!$B:$B,">="&DATE(2025,12,1),Raw_Orders!$B:$B,"<="&EOMONTH(DATE(2025,12,1),0)) -> 290 | N39: =STDEV(B39:M39) -> 79.674337 | O39: =N39/SQRT(30.4) -> 14.45046
A40: =Raw_Inventory!A11 -> SKU-010 | B40: =SUMIFS(Raw_Orders!$H:$H,Raw_Orders!$E:$E,'Reorder EOQ Planner '!A40,Raw_Orders!$B:$B,">="&DATE(2025,1,1),Raw_Orders!$B:$B,"<="&EOMONTH(DATE(2025,1,1),0)) -> 418 | C40: =SUMIFS(Raw_Orders!$H:$H,Raw_Orders!$E:$E,'Reorder EOQ Planner '!A40,Raw_Orders!$B:$B,">="&DATE(2025,2,1),Raw_Orders!$B:$B,"<="&EOMONTH(DATE(2025,2,1),0)) -> 389 | D40: =SUMIFS(Raw_Orders!$H:$H,Raw_Orders!$E:$E,'Reorder EOQ Planner '!A40,Raw_Orders!$B:$B,">="&DATE(2025,3,1),Raw_Orders!$B:$B,"<="&EOMONTH(DATE(2025,3,1),0)) -> 401 | E40: =SUMIFS(Raw_Orders!$H:$H,Raw_Orders!$E:$E,'Reorder EOQ Planner '!$A40,Raw_Orders!$B:$B,">="&DATE(2025,4,1),Raw_Orders!$B:$B,"<="&EOMONTH(DATE(2025,4,1),0)) -> 607 | F40: =SUMIFS(Raw_Orders!$H:$H,Raw_Orders!$E:$E,'Reorder EOQ Planner '!$A40,Raw_Orders!$B:$B,">="&DATE(2025,5,1),Raw_Orders!$B:$B,"<="&EOMONTH(DATE(2025,5,1),0)) -> 347 | G40: =SUMIFS(Raw_Orders!$H:$H,Raw_Orders!$E:$E,'Reorder EOQ Planner '!$A40,Raw_Orders!$B:$B,">="&DATE(2025,6,1),Raw_Orders!$B:$B,"<="&EOMONTH(DATE(2025,6,1),0)) -> 579 | H40: =SUMIFS(Raw_Orders!$H:$H,Raw_Orders!$E:$E,'Reorder EOQ Planner '!$A40,Raw_Orders!$B:$B,">="&DATE(2025,7,1),Raw_Orders!$B:$B,"<="&EOMONTH(DATE(2025,7,1),0)) -> 534 | I40: =SUMIFS(Raw_Orders!$H:$H,Raw_Orders!$E:$E,'Reorder EOQ Planner '!$A40,Raw_Orders!$B:$B,">="&DATE(2025,8,1),Raw_Orders!$B:$B,"<="&EOMONTH(DATE(2025,8,1),0)) -> 385 | J40: =SUMIFS(Raw_Orders!$H:$H,Raw_Orders!$E:$E,'Reorder EOQ Planner '!$A40,Raw_Orders!$B:$B,">="&DATE(2025,9,1),Raw_Orders!$B:$B,"<="&EOMONTH(DATE(2025,9,1),0)) -> 690 | K40: =SUMIFS(Raw_Orders!$H:$H,Raw_Orders!$E:$E,'Reorder EOQ Planner '!$A40,Raw_Orders!$B:$B,">="&DATE(2025,10,1),Raw_Orders!$B:$B,"<="&EOMONTH(DATE(2025,10,1),0)) -> 698 | L40: =SUMIFS(Raw_Orders!$H:$H,Raw_Orders!$E:$E,'Reorder EOQ Planner '!$A40,Raw_Orders!$B:$B,">="&DATE(2025,11,1),Raw_Orders!$B:$B,"<="&EOMONTH(DATE(2025,11,1),0)) -> 738 | M40: =SUMIFS(Raw_Orders!$H:$H,Raw_Orders!$E:$E,'Reorder EOQ Planner '!$A40,Raw_Orders!$B:$B,">="&DATE(2025,12,1),Raw_Orders!$B:$B,"<="&EOMONTH(DATE(2025,12,1),0)) -> 751 | N40: =STDEV(B40:M40) -> 152.32867 | O40: =N40/SQRT(30.4) -> 27.627707
A41: =Raw_Inventory!A12 -> SKU-011 | B41: =SUMIFS(Raw_Orders!$H:$H,Raw_Orders!$E:$E,'Reorder EOQ Planner '!A41,Raw_Orders!$B:$B,">="&DATE(2025,1,1),Raw_Orders!$B:$B,"<="&EOMONTH(DATE(2025,1,1),0)) -> 588 | C41: =SUMIFS(Raw_Orders!$H:$H,Raw_Orders!$E:$E,'Reorder EOQ Planner '!A41,Raw_Orders!$B:$B,">="&DATE(2025,2,1),Raw_Orders!$B:$B,"<="&EOMONTH(DATE(2025,2,1),0)) -> 265 | D41: =SUMIFS(Raw_Orders!$H:$H,Raw_Orders!$E:$E,'Reorder EOQ Planner '!A41,Raw_Orders!$B:$B,">="&DATE(2025,3,1),Raw_Orders!$B:$B,"<="&EOMONTH(DATE(2025,3,1),0)) -> 784 | E41: =SUMIFS(Raw_Orders!$H:$H,Raw_Orders!$E:$E,'Reorder EOQ Planner '!$A41,Raw_Orders!$B:$B,">="&DATE(2025,4,1),Raw_Orders!$B:$B,"<="&EOMONTH(DATE(2025,4,1),0)) -> 501 | F41: =SUMIFS(Raw_Orders!$H:$H,Raw_Orders!$E:$E,'Reorder EOQ Planner '!$A41,Raw_Orders!$B:$B,">="&DATE(2025,5,1),Raw_Orders!$B:$B,"<="&EOMONTH(DATE(2025,5,1),0)) -> 574 | G41: =SUMIFS(Raw_Orders!$H:$H,Raw_Orders!$E:$E,'Reorder EOQ Planner '!$A41,Raw_Orders!$B:$B,">="&DATE(2025,6,1),Raw_Orders!$B:$B,"<="&EOMONTH(DATE(2025,6,1),0)) -> 569 | H41: =SUMIFS(Raw_Orders!$H:$H,Raw_Orders!$E:$E,'Reorder EOQ Planner '!$A41,Raw_Orders!$B:$B,">="&DATE(2025,7,1),Raw_Orders!$B:$B,"<="&EOMONTH(DATE(2025,7,1),0)) -> 583 | I41: =SUMIFS(Raw_Orders!$H:$H,Raw_Orders!$E:$E,'Reorder EOQ Planner '!$A41,Raw_Orders!$B:$B,">="&DATE(2025,8,1),Raw_Orders!$B:$B,"<="&EOMONTH(DATE(2025,8,1),0)) -> 639 | J41: =SUMIFS(Raw_Orders!$H:$H,Raw_Orders!$E:$E,'Reorder EOQ Planner '!$A41,Raw_Orders!$B:$B,">="&DATE(2025,9,1),Raw_Orders!$B:$B,"<="&EOMONTH(DATE(2025,9,1),0)) -> 530 | K41: =SUMIFS(Raw_Orders!$H:$H,Raw_Orders!$E:$E,'Reorder EOQ Planner '!$A41,Raw_Orders!$B:$B,">="&DATE(2025,10,1),Raw_Orders!$B:$B,"<="&EOMONTH(DATE(2025,10,1),0)) -> 737 | L41: =SUMIFS(Raw_Orders!$H:$H,Raw_Orders!$E:$E,'Reorder EOQ Planner '!$A41,Raw_Orders!$B:$B,">="&DATE(2025,11,1),Raw_Orders!$B:$B,"<="&EOMONTH(DATE(2025,11,1),0)) -> 632 | M41: =SUMIFS(Raw_Orders!$H:$H,Raw_Orders!$E:$E,'Reorder EOQ Planner '!$A41,Raw_Orders!$B:$B,">="&DATE(2025,12,1),Raw_Orders!$B:$B,"<="&EOMONTH(DATE(2025,12,1),0)) -> 685 | N41: =STDEV(B41:M41) -> 131.53877 | O41: =N41/SQRT(30.4) -> 23.857063
A42: =Raw_Inventory!A13 -> SKU-012 | B42: =SUMIFS(Raw_Orders!$H:$H,Raw_Orders!$E:$E,'Reorder EOQ Planner '!A42,Raw_Orders!$B:$B,">="&DATE(2025,1,1),Raw_Orders!$B:$B,"<="&EOMONTH(DATE(2025,1,1),0)) -> 235 | C42: =SUMIFS(Raw_Orders!$H:$H,Raw_Orders!$E:$E,'Reorder EOQ Planner '!A42,Raw_Orders!$B:$B,">="&DATE(2025,2,1),Raw_Orders!$B:$B,"<="&EOMONTH(DATE(2025,2,1),0)) -> 364 | D42: =SUMIFS(Raw_Orders!$H:$H,Raw_Orders!$E:$E,'Reorder EOQ Planner '!A42,Raw_Orders!$B:$B,">="&DATE(2025,3,1),Raw_Orders!$B:$B,"<="&EOMONTH(DATE(2025,3,1),0)) -> 295 | E42: =SUMIFS(Raw_Orders!$H:$H,Raw_Orders!$E:$E,'Reorder EOQ Planner '!$A42,Raw_Orders!$B:$B,">="&DATE(2025,4,1),Raw_Orders!$B:$B,"<="&EOMONTH(DATE(2025,4,1),0)) -> 210 | F42: =SUMIFS(Raw_Orders!$H:$H,Raw_Orders!$E:$E,'Reorder EOQ Planner '!$A42,Raw_Orders!$B:$B,">="&DATE(2025,5,1),Raw_Orders!$B:$B,"<="&EOMONTH(DATE(2025,5,1),0)) -> 302 | G42: =SUMIFS(Raw_Orders!$H:$H,Raw_Orders!$E:$E,'Reorder EOQ Planner '!$A42,Raw_Orders!$B:$B,">="&DATE(2025,6,1),Raw_Orders!$B:$B,"<="&EOMONTH(DATE(2025,6,1),0)) -> 390 | H42: =SUMIFS(Raw_Orders!$H:$H,Raw_Orders!$E:$E,'Reorder EOQ Planner '!$A42,Raw_Orders!$B:$B,">="&DATE(2025,7,1),Raw_Orders!$B:$B,"<="&EOMONTH(DATE(2025,7,1),0)) -> 395 | I42: =SUMIFS(Raw_Orders!$H:$H,Raw_Orders!$E:$E,'Reorder EOQ Planner '!$A42,Raw_Orders!$B:$B,">="&DATE(2025,8,1),Raw_Orders!$B:$B,"<="&EOMONTH(DATE(2025,8,1),0)) -> 325 | J42: =SUMIFS(Raw_Orders!$H:$H,Raw_Orders!$E:$E,'Reorder EOQ Planner '!$A42,Raw_Orders!$B:$B,">="&DATE(2025,9,1),Raw_Orders!$B:$B,"<="&EOMONTH(DATE(2025,9,1),0)) -> 359 | K42: =SUMIFS(Raw_Orders!$H:$H,Raw_Orders!$E:$E,'Reorder EOQ Planner '!$A42,Raw_Orders!$B:$B,">="&DATE(2025,10,1),Raw_Orders!$B:$B,"<="&EOMONTH(DATE(2025,10,1),0)) -> 493 | L42: =SUMIFS(Raw_Orders!$H:$H,Raw_Orders!$E:$E,'Reorder EOQ Planner '!$A42,Raw_Orders!$B:$B,">="&DATE(2025,11,1),Raw_Orders!$B:$B,"<="&EOMONTH(DATE(2025,11,1),0)) -> 442 | M42: =SUMIFS(Raw_Orders!$H:$H,Raw_Orders!$E:$E,'Reorder EOQ Planner '!$A42,Raw_Orders!$B:$B,">="&DATE(2025,12,1),Raw_Orders!$B:$B,"<="&EOMONTH(DATE(2025,12,1),0)) -> 555 | N42: =STDEV(B42:M42) -> 100.61188 | O42: =N42/SQRT(30.4) -> 18.247882
... A45: =Raw_Inventory!A16 -> SKU-015 | B45: =SUMIFS(Raw_Orders!$H:$H,Raw_Orders!$E:$E,'Reorder EOQ Planner '!A45,Raw_Orders!$B:$B,">="&DATE(2025,1,1),Raw_Orders!$B:$B,"<="&EOMONTH(DATE(2025,1,1),0)) -> 117 | C45: =SUMIFS(Raw_Orders!$H:$H,Raw_Orders!$E:$E,'Reorder EOQ Planner '!A45,Raw_Orders!$B:$B,">="&DATE(2025,2,1),Raw_Orders!$B:$B,"<="&EOMONTH(DATE(2025,2,1),0)) -> 100 | D45: =SUMIFS(Raw_Orders!$H:$H,Raw_Orders!$E:$E,'Reorder EOQ Planner '!A45,Raw_Orders!$B:$B,">="&DATE(2025,3,1),Raw_Orders!$B:$B,"<="&EOMONTH(DATE(2025,3,1),0)) -> 90 | E45: =SUMIFS(Raw_Orders!$H:$H,Raw_Orders!$E:$E,'Reorder EOQ Planner '!$A45,Raw_Orders!$B:$B,">="&DATE(2025,4,1),Raw_Orders!$B:$B,"<="&EOMONTH(DATE(2025,4,1),0)) -> 120 | F45: =SUMIFS(Raw_Orders!$H:$H,Raw_Orders!$E:$E,'Reorder EOQ Planner '!$A45,Raw_Orders!$B:$B,">="&DATE(2025,5,1),Raw_Orders!$B:$B,"<="&EOMONTH(DATE(2025,5,1),0)) -> 108 | G45: =SUMIFS(Raw_Orders!$H:$H,Raw_Orders!$E:$E,'Reorder EOQ Planner '!$A45,Raw_Orders!$B:$B,">="&DATE(2025,6,1),Raw_Orders!$B:$B,"<="&EOMONTH(DATE(2025,6,1),0)) -> 89 | H45: =SUMIFS(Raw_Orders!$H:$H,Raw_Orders!$E:$E,'Reorder EOQ Planner '!$A45,Raw_Orders!$B:$B,">="&DATE(2025,7,1),Raw_Orders!$B:$B,"<="&EOMONTH(DATE(2025,7,1),0)) -> 128 | I45: =SUMIFS(Raw_Orders!$H:$H,Raw_Orders!$E:$E,'Reorder EOQ Planner '!$A45,Raw_Orders!$B:$B,">="&DATE(2025,8,1),Raw_Orders!$B:$B,"<="&EOMONTH(DATE(2025,8,1),0)) -> 164 | J45: =SUMIFS(Raw_Orders!$H:$H,Raw_Orders!$E:$E,'Reorder EOQ Planner '!$A45,Raw_Orders!$B:$B,">="&DATE(2025,9,1),Raw_Orders!$B:$B,"<="&EOMONTH(DATE(2025,9,1),0)) -> 99 | K45: =SUMIFS(Raw_Orders!$H:$H,Raw_Orders!$E:$E,'Reorder EOQ Planner '!$A45,Raw_Orders!$B:$B,">="&DATE(2025,10,1),Raw_Orders!$B:$B,"<="&EOMONTH(DATE(2025,10,1),0)) -> 149 | L45: =SUMIFS(Raw_Orders!$H:$H,Raw_Orders!$E:$E,'Reorder EOQ Planner '!$A45,Raw_Orders!$B:$B,">="&DATE(2025,11,1),Raw_Orders!$B:$B,"<="&EOMONTH(DATE(2025,11,1),0)) -> 188 | M45: =SUMIFS(Raw_Orders!$H:$H,Raw_Orders!$E:$E,'Reorder EOQ Planner '!$A45,Raw_Orders!$B:$B,">="&DATE(2025,12,1),Raw_Orders!$B:$B,"<="&EOMONTH(DATE(2025,12,1),0)) -> 107 | N45: =STDEV(B45:M45) -> 30.835217 | O45: =N45/SQRT(30.4) -> 5.5925544

Sheet Demand forecast
A1: Demand Forecast ( 3-Month Moving Average, With MAPE Accuracy Check )
A2: Total unit ordered per month (all SKUs), a simple moving-average forcast, and a MAPE score measuring how accurate the forecast acctualy was
A4: Month | B4: Month Start | C4: Month End | D4: Actual Unit Sold | E4: 3-Month Moving Avereg Forecast | F4: MoM Growth % | G4: Absolute_%_Error (MAPE input)
A5: 45658 | B5: 45658 | C5: 45688 | D5: =SUMIFS(Raw_Orders!$H:$H,Raw_Orders!$B:$B,">="&'Demand forecast'!B5,Raw_Orders!$B:$B,"<="&'Demand forecast'!C5) -> 4498 | E5: n/a-need 3 prior months | F5: n/a | G5: n/a
A6: 45689 | B6: 45689 | C6: 45716 | D6: =SUMIFS(Raw_Orders!$H:$H,Raw_Orders!$B:$B,">="&'Demand forecast'!B6,Raw_Orders!$B:$B,"<="&'Demand forecast'!C6) -> 4188 | E6: n/a-need 3 prior months | F6: =IFERROR((D5-D6)/D5,"n/a") -> 0.06891952 | G6: n/a
A7: 45717 | B7: 45717 | C7: 45747 | D7: =SUMIFS(Raw_Orders!$H:$H,Raw_Orders!$B:$B,">="&'Demand forecast'!B7,Raw_Orders!$B:$B,"<="&'Demand forecast'!C7) -> 5054 | E7: n/a-need 3 prior months | F7: =IFERROR((D6-D7)/D6,"n/a") -> -0.20678128 | G7: n/a
A8: 45748 | B8: 45748 | C8: 45777 | D8: =SUMIFS(Raw_Orders!$H:$H,Raw_Orders!$B:$B,">="&'Demand forecast'!B8,Raw_Orders!$B:$B,"<="&'Demand forecast'!C8) -> 4070 | E8: =AVERAGE(D5:D7) -> 4580 | F8: =IFERROR((D7-D8)/D7,"n/a") -> 0.19469727 | G8: =ABS(D8-E8)/D8 -> 0.12530713
A9: 45778 | B9: 45778 | C9: 45808 | D9: =SUMIFS(Raw_Orders!$H:$H,Raw_Orders!$B:$B,">="&'Demand forecast'!B9,Raw_Orders!$B:$B,"<="&'Demand forecast'!C9) -> 4905 | E9: =AVERAGE(D6:D8) -> 4437.3333 | F9: =IFERROR((D8-D9)/D8,"n/a") -> -0.20515971 | G9: =ABS(D9-E9)/D9 -> 0.095344886
A10: 45809 | B10: 45809 | C10: 45838 | D10: =SUMIFS(Raw_Orders!$H:$H,Raw_Orders!$B:$B,">="&'Demand forecast'!B10,Raw_Orders!$B:$B,"<="&'Demand forecast'!C10) -> 4531 | E10: =AVERAGE(D7:D9) -> 4676.3333 | F10: =IFERROR((D9-D10)/D9,"n/a") -> 0.076248726 | G10: =ABS(D10-E10)/D10 -> 0.032075333
A11: 45839 | B11: 45839 | C11: 45869 | D11: =SUMIFS(Raw_Orders!$H:$H,Raw_Orders!$B:$B,">="&'Demand forecast'!B11,Raw_Orders!$B:$B,"<="&'Demand forecast'!C11) -> 5290 | E11: =AVERAGE(D8:D10) -> 4502 | F11: =IFERROR((D10-D11)/D10,"n/a") -> -0.16751269 | G11: =ABS(D11-E11)/D11 -> 0.1489603
